Workbook
Name SayfaListesi: _xludf.GET.WORKBOOK(1)

Sheet STOK KULLANIM
A1: TARİH | B1: PROJE | C1: TÜR | D1: MALZEME | E1: KALİTE | F1: KESİLECEK PARÇA ADEDİ | G1: KESİLECEK PARÇA BOYU | H1: GEREKLİ ADET | I1: BOY | J1: FİRE | K1: EŞİT FİRE | L1: SONDAN KALAN FİRE | O1: BIÇAK PAYI | P1: HURDA< | XEV1: 6000 | XEZ1: KUTU PROFİL | XFC1: S235JR
H2: =IFERROR(IF( SK[[#This Row],[KESİLECEK PARÇA ADEDİ ]]*SK[[#This Row],[KESİLECEK PARÇA BOYU]] < SK[[#This Row],[BOY]] - 3*ROUNDUP(SK[[#This Row],[BOY]]/SK[[#This Row],[KESİLECEK PARÇA BOYU]] - 1, 0), 1, ROUNDUP(SK[[#This Row],[KESİLECEK PARÇA ADEDİ ]]/INT(SK[[#This Row],[BOY]]/(SK[[#This Row],[KESİLECEK PARÇA BOYU]]+$O$2)), 0) ),0) -> 0 | I2: 6000 | J2: =IFERROR( IF(SK[[#This Row],[GEREKLİ ADET]]=1, SK[[#This Row],[BOY]]-SK[[#This Row],[KESİLECEK PARÇA ADEDİ ]]*(SK[[#This Row],[KESİLECEK PARÇA BOYU]]+$O$2), IF( MOD(SK[[#This Row],[BOY]],SK[[#This Row],[KESİLECEK PARÇA BOYU]])-$O$2*INT(SK[[#This Row],[BOY]]/SK[[#This Row],[KESİLECEK PARÇA BOYU]])>$P$2, (MOD(SK[[#This Row],[BOY]],SK[[#This Row],[KESİLECEK PARÇA BOYU]])-$O$2*INT(SK[[#This Row],[BOY]]/SK[[#This Row],[KESİLECEK PARÇA BOYU]]))*SK[[#This Row],[GEREKLİ ADET]], 0 ) ) + IF(SK[[#This Row],[GEREKLİ ADET]]>1, IF( INT((SK[[#This Row],[BOY]]+$O$2)/(SK[[#This Row],[KESİLECEK PARÇA BOYU]]+$O$2))=0, 0, IF( (SK[[#This Row],[BOY]]-MOD(SK[[#This Row],[KESİLECEK PARÇA ADEDİ ]], INT((SK[[#This Row],[BOY]]+$O$2)/(SK[[#This Row],[KESİLECEK PARÇA BOYU]]+$O$2)) )*(SK[[#This Row],[KESİLECEK PARÇA BOYU]]+$O$2))>$P$2, IF( MOD(SK[[#This Row],[KESİLECEK PARÇA ADEDİ ]], INT((SK[[#This Row],[BOY]]+$O$2)/(SK[[#This Row],[KESİLECEK PARÇA BOYU]]+$O$2)))=0, 0, SK[[#This Row],[BOY]]-MOD(SK[[#This Row],[KESİLECEK PARÇA ADEDİ ]], INT((SK[[#This Row],[BOY]]+$O$2)/(SK[[#This Row],[KESİLECEK PARÇA BOYU]]+$O$2)))*(SK[[#This Row],[KESİLECEK PARÇA BOYU]]+$O$2) ), 0 ) ), 0 ), 0) -> 0 | K2: =IFERROR( IF( IF( MOD(SK[[#This Row],[BOY]],SK[[#This Row],[KESİLECEK PARÇA BOYU]])-$O$2*INT(SK[[#This Row],[BOY]]/SK[[#This Row],[KESİLECEK PARÇA BOYU]])>$P$2, (MOD(SK[[#This Row],[BOY]],SK[[#This Row],[KESİLECEK PARÇA BOYU]])-$O$2*INT(SK[[#This Row],[BOY]]/SK[[#This Row],[KESİLECEK PARÇA BOYU]])), 0 )>0,IF( MOD(SK[[#This Row],[BOY]],SK[[#This Row],[KESİLECEK PARÇA BOYU]])-$O$2*INT(SK[[#This Row],[BOY]]/SK[[#This Row],[KESİLECEK PARÇA BOYU]])>$P$2, (MOD(SK[[#This Row],[BOY]],SK[[#This Row],[KESİLECEK PARÇA BOYU]])-$O$2*INT(SK[[#This Row],[BOY]]/SK[[#This Row],[KESİLECEK PARÇA BOYU]])), 0 ),0),0) -> 0 | L2: =IFERROR(IF(SK[[#This Row],[BOY]]-(SK[[#This Row],[KESİLECEK PARÇA BOYU]]+$O$2)*MOD(SK[[#This Row],[KESİLECEK PARÇA ADEDİ ]],INT(SK[[#This Row],[BOY]]/(SK[[#This Row],[KESİLECEK PARÇA BOYU]]+$O$2)))<SK[[#This Row],[BOY]],SK[[#This Row],[BOY]]-(SK[[#This Row],[KESİLECEK PARÇA BOYU]]+$O$2)*MOD(SK[[#This Row],[KESİLECEK PARÇA ADEDİ ]],INT(SK[[#This Row],[BOY]]/(SK[[#This Row],[KESİLECEK PARÇA BOYU]]+$O$2))),0),0) -> 0 | O2: 3 | P2: 1000 | XEV2: 12000 | XEZ2: BORU PROFİL | XFC2: S355J2H
H3: =IFERROR(IF( SK[[#This Row],[KESİLECEK PARÇA ADEDİ ]]*SK[[#This Row],[KESİLECEK PARÇA BOYU]] < SK[[#This Row],[BOY]] - 3*ROUNDUP(SK[[#This Row],[BOY]]/SK[[#This Row],[KESİLECEK PARÇA BOYU]] - 1, 0), 1, ROUNDUP(SK[[#This Row],[KESİLECEK PARÇA ADEDİ ]]/INT(SK[[#This Row],[BOY]]/(SK[[#This Row],[KESİLECEK PARÇA BOYU]]+$O$2)), 0) ),0) -> 0 | I3: 6000 | J3: =IFERROR( IF(SK[[#This Row],[GEREKLİ ADET]]=1, SK[[#This Row],[BOY]]-SK[[#This Row],[KESİLECEK PARÇA ADEDİ ]]*(SK[[#This Row],[KESİLECEK PARÇA BOYU]]+$O$2), IF( MOD(SK[[#This Row],[BOY]],SK[[#This Row],[KESİLECEK PARÇA BOYU]])-$O$2*INT(SK[[#This Row],[BOY]]/SK[[#This Row],[KESİLECEK PARÇA BOYU]])>$P$2, (MOD(SK[[#This Row],[BOY]],SK[[#This Row],[KESİLECEK PARÇA BOYU]])-$O$2*INT(SK[[#This Row],[BOY]]/SK[[#This Row],[KESİLECEK PARÇA BOYU]]))*SK[[#This Row],[GEREKLİ ADET]], 0 ) ) + IF(SK[[#This Row],[GEREKLİ ADET]]>1, IF( INT((SK[[#This Row],[BOY]]+$O$2)/(SK[[#This Row],[KESİLECEK PARÇA BOYU]]+$O$2))=0, 0, IF( (SK[[#This Row],[BOY]]-MOD(SK[[#This Row],[KESİLECEK PARÇA ADEDİ ]], INT((SK[[#This Row],[BOY]]+$O$2)/(SK[[#This Row],[KESİLECEK PARÇA BOYU]]+$O$2)) )*(SK[[#This Row],[KESİLECEK PARÇA BOYU]]+$O$2))>$P$2, IF( MOD(SK[[#This Row],[KESİLECEK PARÇA ADEDİ ]], INT((SK[[#This Row],[BOY]]+$O$2)/(SK[[#This Row],[KESİLECEK PARÇA BOYU]]+$O$2)))=0, 0, SK[[#This Row],[BOY]]-MOD(SK[[#This Row],[KESİLECEK PARÇA ADEDİ ]], INT((SK[[#This Row],[BOY]]+$O$2)/(SK[[#This Row],[KESİLECEK PARÇA BOYU]]+$O$2)))*(SK[[#This Row],[KESİLECEK PARÇA BOYU]]+$O$2) ), 0 ) ), 0 ), 0) -> 0 | K3: =IFERROR( IF( IF( MOD(SK[[#This Row],[BOY]],SK[[#This Row],[KESİLECEK PARÇA BOYU]])-$O$2*INT(SK[[#This Row],[BOY]]/SK[[#This Row],[KESİLECEK PARÇA BOYU]])>$P$2, (MOD(SK[[#This Row],[BOY]],SK[[#This Row],[KESİLECEK PARÇA BOYU]])-$O$2*INT(SK[[#This Row],[BOY]]/SK[[#This Row],[KESİLECEK PARÇA BOYU]])), 0 )>0,IF( MOD(SK[[#This Row],[BOY]],SK[[#This Row],[KESİLECEK PARÇA BOYU]])-$O$2*INT(SK[[#This Row],[BOY]]/SK[[#This Row],[KESİLECEK PARÇA BOYU]])>$P$2, (MOD(SK[[#This Row],[BOY]],SK[[#This Row],[KESİLECEK PARÇA BOYU]])-$O$2*INT(SK[[#This Row],[BOY]]/SK[[#This Row],[KESİLECEK PARÇA BOYU]])), 0 ),0),0) -> 0 | L3: =IFERROR(IF(SK[[#This Row],[BOY]]-(SK[[#This Row],[KESİLECEK PARÇA BOYU]]+$O$2)*MOD(SK[[#This Row],[KESİLECEK PARÇA ADEDİ ]],INT(SK[[#This Row],[BOY]]/(SK[[#This Row],[KESİLECEK PARÇA BOYU]]+$O$2)))<SK[[#This Row],[BOY]],SK[[#This Row],[BOY]]-(SK[[#This Row],[KESİLECEK PARÇA BOYU]]+$O$2)*MOD(SK[[#This Row],[KESİLECEK PARÇA ADEDİ ]],INT(SK[[#This Row],[BOY]]/(SK[[#This Row],[KESİLECEK PARÇA BOYU]]+$O$2))),0),0) -> 0 | XEZ3: HEA PROFİL | XFC3: S355JR
H4: =IFERROR(IF( SK[[#This Row],[KESİLECEK PARÇA ADEDİ ]]*SK[[#This Row],[KESİLECEK PARÇA BOYU]] < SK[[#This Row],[BOY]] - 3*ROUNDUP(SK[[#This Row],[BOY]]/SK[[#This Row],[KESİLECEK PARÇA BOYU]] - 1, 0), 1, ROUNDUP(SK[[#This Row],[KESİLECEK PARÇA ADEDİ ]]/INT(SK[[#This Row],[BOY]]/(SK[[#This Row],[KESİLECEK PARÇA BOYU]]+$O$2)), 0) ),0) -> 0 | I4: 12000 | J4: =IFERROR( IF(SK[[#This Row],[GEREKLİ ADET]]=1, SK[[#This Row],[BOY]]-SK[[#This Row],[KESİLECEK PARÇA ADEDİ ]]*(SK[[#This Row],[KESİLECEK PARÇA BOYU]]+$O$2), IF( MOD(SK[[#This Row],[BOY]],SK[[#This Row],[KESİLECEK PARÇA BOYU]])-$O$2*INT(SK[[#This Row],[BOY]]/SK[[#This Row],[KESİLECEK PARÇA BOYU]])>$P$2, (MOD(SK[[#This Row],[BOY]],SK[[#This Row],[KESİLECEK PARÇA BOYU]])-$O$2*INT(SK[[#This Row],[BOY]]/SK[[#This Row],[KESİLECEK PARÇA BOYU]]))*SK[[#This Row],[GEREKLİ ADET]], 0 ) ) + IF(SK[[#This Row],[GEREKLİ ADET]]>1, IF( INT((SK[[#This Row],[BOY]]+$O$2)/(SK[[#This Row],[KESİLECEK PARÇA BOYU]]+$O$2))=0, 0, IF( (SK[[#This Row],[BOY]]-MOD(SK[[#This Row],[KESİLECEK PARÇA ADEDİ ]], INT((SK[[#This Row],[BOY]]+$O$2)/(SK[[#This Row],[KESİLECEK PARÇA BOYU]]+$O$2)) )*(SK[[#This Row],[KESİLECEK PARÇA BOYU]]+$O$2))>$P$2, IF( MOD(SK[[#This Row],[KESİLECEK PARÇA ADEDİ ]], INT((SK[[#This Row],[BOY]]+$O$2)/(SK[[#This Row],[KESİLECEK PARÇA BOYU]]+$O$2)))=0, 0, SK[[#This Row],[BOY]]-MOD(SK[[#This Row],[KESİLECEK PARÇA ADEDİ ]], INT((SK[[#This Row],[BOY]]+$O$2)/(SK[[#This Row],[KESİLECEK PARÇA BOYU]]+$O$2)))*(SK[[#This Row],[KESİLECEK PARÇA BOYU]]+$O$2) ), 0 ) ), 0 ), 0) -> 0 | K4: =IFERROR( IF( IF( MOD(SK[[#This Row],[BOY]],SK[[#This Row],[KESİLECEK PARÇA BOYU]])-$O$2*INT(SK[[#This Row],[BOY]]/SK[[#This Row],[KESİLECEK PARÇA BOYU]])>$P$2, (MOD(SK[[#This Row],[BOY]],SK[[#This Row],[KESİLECEK PARÇA BOYU]])-$O$2*INT(SK[[#This Row],[BOY]]/SK[[#This Row],[KESİLECEK PARÇA BOYU]])), 0 )>0,IF( MOD(SK[[#This Row],[BOY]],SK[[#This Row],[KESİLECEK PARÇA BOYU]])-$O$2*INT(SK[[#This Row],[BOY]]/SK[[#This Row],[KESİLECEK PARÇA BOYU]])>$P$2, (MOD(SK[[#This Row],[BOY]],SK[[#This Row],[KESİLECEK PARÇA BOYU]])-$O$2*INT(SK[[#This Row],[BOY]]/SK[[#This Row],[KESİLECEK PARÇA BOYU]])), 0 ),0),0) -> 0 | L4: =IFERROR(IF(SK[[#This Row],[BOY]]-(SK[[#This Row],[KESİLECEK PARÇA BOYU]]+$O$2)*MOD(SK[[#This Row],[KESİLECEK PARÇA ADEDİ ]],INT(SK[[#This Row],[BOY]]/(SK[[#This Row],[KESİLECEK PARÇA BOYU]]+$O$2)))<SK[[#This Row],[BOY]],SK[[#This Row],[BOY]]-(SK[[#This Row],[KESİLECEK PARÇA BOYU]]+$O$2)*MOD(SK[[#This Row],[KESİLECEK PARÇA ADEDİ ]],INT(SK[[#This Row],[BOY]]/(SK[[#This Row],[KESİLECEK PARÇA BOYU]]+$O$2))),0),0) -> 0 | XEZ4: HEB PROFİL | XFC4: S355J2
H5: =IFERROR(IF( SK[[#This Row],[KESİLECEK PARÇA ADEDİ ]]*SK[[#This Row],[KESİLECEK PARÇA BOYU]] < SK[[#This Row],[BOY]] - 3*ROUNDUP(SK[[#This Row],[BOY]]/SK[[#This Row],[KESİLECEK PARÇA BOYU]] - 1, 0), 1, ROUNDUP(SK[[#This Row],[KESİLECEK PARÇA ADEDİ ]]/INT(SK[[#This Row],[BOY]]/(SK[[#This Row],[KESİLECEK PARÇA BOYU]]+$O$2)), 0) ),0) -> 0 | I5: 6000 | J5: =IFERROR( IF(SK[[#This Row],[GEREKLİ ADET]]=1, SK[[#This Row],[BOY]]-SK[[#This Row],[KESİLECEK PARÇA ADEDİ ]]*(SK[[#This Row],[KESİLECEK PARÇA BOYU]]+$O$2), IF( MOD(SK[[#This Row],[BOY]],SK[[#This Row],[KESİLECEK PARÇA BOYU]])-$O$2*INT(SK[[#This Row],[BOY]]/SK[[#This Row],[KESİLECEK PARÇA BOYU]])>$P$2, (MOD(SK[[#This Row],[BOY]],SK[[#This Row],[KESİLECEK PARÇA BOYU]])-$O$2*INT(SK[[#This Row],[BOY]]/SK[[#This Row],[KESİLECEK PARÇA BOYU]]))*SK[[#This Row],[GEREKLİ ADET]], 0 ) ) + IF(SK[[#This Row],[GEREKLİ ADET]]>1, IF( INT((SK[[#This Row],[BOY]]+$O$2)/(SK[[#This Row],[KESİLECEK PARÇA BOYU]]+$O$2))=0, 0, IF( (SK[[#This Row],[BOY]]-MOD(SK[[#This Row],[KESİLECEK PARÇA ADEDİ ]], INT((SK[[#This Row],[BOY]]+$O$2)/(SK[[#This Row],[KESİLECEK PARÇA BOYU]]+$O$2)) )*(SK[[#This Row],[KESİLECEK PARÇA BOYU]]+$O$2))>$P$2, IF( MOD(SK[[#This Row],[KESİLECEK PARÇA ADEDİ ]], INT((SK[[#This Row],[BOY]]+$O$2)/(SK[[#This Row],[KESİLECEK PARÇA BOYU]]+$O$2)))=0, 0, SK[[#This Row],[BOY]]-MOD(SK[[#This Row],[KESİLECEK PARÇA ADEDİ ]], INT((SK[[#This Row],[BOY]]+$O$2)/(SK[[#This Row],[KESİLECEK PARÇA BOYU]]+$O$2)))*(SK[[#This Row],[KESİLECEK PARÇA BOYU]]+$O$2) ), 0 ) ), 0 ), 0) -> 0 | K5: =IFERROR( IF( IF( MOD(SK[[#This Row],[BOY]],SK[[#This Row],[KESİLECEK PARÇA BOYU]])-$O$2*INT(SK[[#This Row],[BOY]]/SK[[#This Row],[KESİLECEK PARÇA BOYU]])>$P$2, (MOD(SK[[#This Row],[BOY]],SK[[#This Row],[KESİLECEK PARÇA BOYU]])-$O$2*INT(SK[[#This Row],[BOY]]/SK[[#This Row],[KESİLECEK PARÇA BOYU]])), 0 )>0,IF( MOD(SK[[#This Row],[BOY]],SK[[#This Row],[KESİLECEK PARÇA BOYU]])-$O$2*INT(SK[[#This Row],[BOY]]/SK[[#This Row],[KESİLECEK PARÇA BOYU]])>$P$2, (MOD(SK[[#This Row],[BOY]],SK[[#This Row],[KESİLECEK PARÇA BOYU]])-$O$2*INT(SK[[#This Row],[BOY]]/SK[[#This Row],[KESİLECEK PARÇA BOYU]])), 0 ),0),0) -> 0 | L5: =IFERROR(IF(SK[[#This Row],[BOY]]-(SK[[#This Row],[KESİLECEK PARÇA BOYU]]+$O$2)*MOD(SK[[#This Row],[KESİLECEK PARÇA ADEDİ ]],INT(SK[[#This Row],[BOY]]/(SK[[#This Row],[KESİLECEK PARÇA BOYU]]+$O$2)))<SK[[#This Row],[BOY]],SK[[#This Row],[BOY]]-(SK[[#This Row],[KESİLECEK PARÇA BOYU]]+$O$2)*MOD(SK[[#This Row],[KESİLECEK PARÇA ADEDİ ]],INT(SK[[#This Row],[BOY]]/(SK[[#This Row],[KESİLECEK PARÇA BOYU]]+$O$2))),0),0) -> 0 | XEZ5: UNP PROFİL | XFC5: S275JR
H6: =IFERROR(IF( SK[[#This Row],[KESİLECEK PARÇA ADEDİ ]]*SK[[#This Row],[KESİLECEK PARÇA BOYU]] < SK[[#This Row],[BOY]] - 3*ROUNDUP(SK[[#This Row],[BOY]]/SK[[#This Row],[KESİLECEK PARÇA BOYU]] - 1, 0), 1, ROUNDUP(SK[[#This Row],[KESİLECEK PARÇA ADEDİ ]]/INT(SK[[#This Row],[BOY]]/(SK[[#This Row],[KESİLECEK PARÇA BOYU]]+$O$2)), 0) ),0) -> 0 | J6: =IFERROR( IF(SK[[#This Row],[GEREKLİ ADET]]=1, SK[[#This Row],[BOY]]-SK[[#This Row],[KESİLECEK PARÇA ADEDİ ]]*(SK[[#This Row],[KESİLECEK PARÇA BOYU]]+$O$2), IF( MOD(SK[[#This Row],[BOY]],SK[[#This Row],[KESİLECEK PARÇA BOYU]])-$O$2*INT(SK[[#This Row],[BOY]]/SK[[#This Row],[KESİLECEK PARÇA BOYU]])>$P$2, (MOD(SK[[#This Row],[BOY]],SK[[#This Row],[KESİLECEK PARÇA BOYU]])-$O$2*INT(SK[[#This Row],[BOY]]/SK[[#This Row],[KESİLECEK PARÇA BOYU]]))*SK[[#This Row],[GEREKLİ ADET]], 0 ) ) + IF(SK[[#This Row],[GEREKLİ ADET]]>1, IF( INT((SK[[#This Row],[BOY]]+$O$2)/(SK[[#This Row],[KESİLECEK PARÇA BOYU]]+$O$2))=0, 0, IF( (SK[[#This Row],[BOY]]-MOD(SK[[#This Row],[KESİLECEK PARÇA ADEDİ ]], INT((SK[[#This Row],[BOY]]+$O$2)/(SK[[#This Row],[KESİLECEK PARÇA BOYU]]+$O$2)) )*(SK[[#This Row],[KESİLECEK PARÇA BOYU]]+$O$2))>$P$2, IF( MOD(SK[[#This Row],[KESİLECEK PARÇA ADEDİ ]], INT((SK[[#This Row],[BOY]]+$O$2)/(SK[[#This Row],[KESİLECEK PARÇA BOYU]]+$O$2)))=0, 0, SK[[#This Row],[BOY]]-MOD(SK[[#This Row],[KESİLECEK PARÇA ADEDİ ]], INT((SK[[#This Row],[BOY]]+$O$2)/(SK[[#This Row],[KESİLECEK PARÇA BOYU]]+$O$2)))*(SK[[#This Row],[KESİLECEK PARÇA BOYU]]+$O$2) ), 0 ) ), 0 ), 0) -> 0 | K6: =IFERROR( IF( IF( MOD(SK[[#This Row],[BOY]],SK[[#This Row],[KESİLECEK PARÇA BOYU]])-$O$2*INT(SK[[#This Row],[BOY]]/SK[[#This Row],[KESİLECEK PARÇA BOYU]])>$P$2, (MOD(SK[[#This Row],[BOY]],SK[[#This Row],[KESİLECEK PARÇA BOYU]])-$O$2*INT(SK[[#This Row],[BOY]]/SK[[#This Row],[KESİLECEK PARÇA BOYU]])), 0 )>0,IF( MOD(SK[[#This Row],[BOY]],SK[[#This Row],[KESİLECEK PARÇA BOYU]])-$O$2*INT(SK[[#This Row],[BOY]]/SK[[#This Row],[KESİLECEK PARÇA BOYU]])>$P$2, (MOD(SK[[#This Row],[BOY]],SK[[#This Row],[KESİLECEK PARÇA BOYU]])-$O$2*INT(SK[[#This Row],[BOY]]/SK[[#This Row],[KESİLECEK PARÇA BOYU]])), 0 ),0),0) -> 0 | L6: =IFERROR(IF(SK[[#This Row],[BOY]]-(SK[[#This Row],[KESİLECEK PARÇA BOYU]]+$O$2)*MOD(SK[[#This Row],[KESİLECEK PARÇA ADEDİ ]],INT(SK[[#This Row],[BOY]]/(SK[[#This Row],[KESİLECEK PARÇA BOYU]]+$O$2)))<SK[[#This Row],[BOY]],SK[[#This Row],[BOY]]-(SK[[#This Row],[KESİLECEK PARÇA BOYU]]+$O$2)*MOD(SK[[#This Row],[KESİLECEK PARÇA ADEDİ ]],INT(SK[[#This Row],[BOY]]/(SK[[#This Row],[KESİLECEK PARÇA BOYU]]+$O$2))),0),0) -> 0 | XEZ6: NPL PROFİL | XFC6: PASLANMAZ
A7: 45895 | B7: 225 | C7: KUTU PROFİL | D7: RHS 100X50X3 | E7: S275JR | F7: 2 | G7: 3000 | H7: =IF(OR(SK[[#This Row],[KESİLECEK PARÇA ADEDİ ]]*(SK[[#This Row],[KESİLECEK PARÇA BOYU]]+O2)<=SK[[#This Row],[BOY]],SK[[#This Row],[KESİLECEK PARÇA ADEDİ ]]*SK[[#This Row],[KESİLECEK PARÇA BOYU]]+O2*(SK[[#This Row],[KESİLECEK PARÇA ADEDİ ]]-1)<=SK[[#This Row],[BOY]]),1,ROUNDUP(SK[[#This Row],[BOY]]/(SK[[#This Row],[KESİLECEK PARÇA BOYU]]+O2),0)) -> 2 | I7: 6000 | J7: =IFERROR( IF(SK[[#This Row],[GEREKLİ ADET]]=1, SK[[#This Row],[BOY]]-SK[[#This Row],[KESİLECEK PARÇA ADEDİ ]]*(SK[[#This Row],[KESİLECEK PARÇA BOYU]]+$O$2), IF( MOD(SK[[#This Row],[BOY]],SK[[#This Row],[KESİLECEK PARÇA BOYU]])-$O$2*INT(SK[[#This Row],[BOY]]/SK[[#This Row],[KESİLECEK PARÇA BOYU]])>$P$2, (MOD(SK[[#This Row],[BOY]],SK[[#This Row],[KESİLECEK PARÇA BOYU]])-$O$2*INT(SK[[#This Row],[BOY]]/SK[[#This Row],[KESİLECEK PARÇA BOYU]]))*SK[[#This Row],[GEREKLİ ADET]], 0 ) ) + IF(SK[[#This Row],[GEREKLİ ADET]]>1, IF( INT(SK[[#This Row],[BOY]]/(SK[[#This Row],[KESİLECEK PARÇA BOYU]]+$O$2))=0, 0, IF( (SK[[#This Row],[BOY]]-MOD(SK[[#This Row],[KESİLECEK PARÇA ADEDİ ]], INT((SK[[#This Row],[BOY]]+$O$2)/(SK[[#This Row],[KESİLECEK PARÇA BOYU]]+$O$2)) )*(SK[[#This Row],[KESİLECEK PARÇA BOYU]]+$O$2))>$P$2, IF( MOD(SK[[#This Row],[KESİLECEK PARÇA ADEDİ ]], INT((SK[[#This Row],[BOY]]+$O$2)/(SK[[#This Row],[KESİLECEK PARÇA BOYU]]+$O$2)))=0, 0, SK[[#This Row],[BOY]]-MOD(SK[[#This Row],[KESİLECEK PARÇA ADEDİ ]], INT((SK[[#This Row],[BOY]]+$O$2)/(SK[[#This Row],[KESİLECEK PARÇA BOYU]]+$O$2)))*(SK[[#This Row],[KESİLECEK PARÇA BOYU]]+$O$2) ), 0 ) ), 0 ), 0) -> 0 | K7: =IFERROR( IF( IF( MOD(SK[[#This Row],[BOY]],SK[[#This Row],[KESİLECEK PARÇA BOYU]])-$O$2*INT(SK[[#This Row],[BOY]]/SK[[#This Row],[KESİLECEK PARÇA BOYU]])>$P$2, (MOD(SK[[#This Row],[BOY]],SK[[#This Row],[KESİLECEK PARÇA BOYU]])-$O$2*INT(SK[[#This Row],[BOY]]/SK[[#This Row],[KESİLECEK PARÇA BOYU]])), 0 )>0,IF( MOD(SK[[#This Row],[BOY]],SK[[#This Row],[KESİLECEK PARÇA BOYU]])-$O$2*INT(SK[[#This Row],[BOY]]/SK[[#This Row],[KESİLECEK PARÇA BOYU]])>$P$2, (MOD(SK[[#This Row],[BOY]],SK[[#This Row],[KESİLECEK PARÇA BOYU]])-$O$2*INT(SK[[#This Row],[BOY]]/SK[[#This Row],[KESİLECEK PARÇA BOYU]])), 0 ),0),0) -> 0 | L7: =IFERROR(IF(SK[[#This Row],[BOY]]-(SK[[#This Row],[KESİLECEK PARÇA BOYU]]+$O$2)*MOD(SK[[#This Row],[KESİLECEK PARÇA ADEDİ ]],INT(SK[[#This Row],[BOY]]/(SK[[#This Row],[KESİLECEK PARÇA BOYU]]+$O$2)))<SK[[#This Row],[BOY]],SK[[#This Row],[BOY]]-(SK[[#This Row],[KESİLECEK PARÇA BOYU]]+$O$2)*MOD(SK[[#This Row],[KESİLECEK PARÇA ADEDİ ]],INT(SK[[#This Row],[BOY]]/(SK[[#This Row],[KESİLECEK PARÇA BOYU]]+$O$2))),0),0) -> 0 | XEZ7: IPE PROFİL | XFC7: S355J0H
H8: =IFERROR(IF( SK[[#This Row],[KESİLECEK PARÇA ADEDİ ]]*SK[[#This Row],[KESİLECEK PARÇA BOYU]] < SK[[#This Row],[BOY]] - 3*ROUNDUP(SK[[#This Row],[BOY]]/SK[[#This Row],[KESİLECEK PARÇA BOYU]] - 1, 0), 1, ROUNDUP(SK[[#This Row],[KESİLECEK PARÇA ADEDİ ]]/INT(SK[[#This Row],[BOY]]/(SK[[#This Row],[KESİLECEK PARÇA BOYU]]+$O$2)), 0) ),0) -> 0 | I8: 12000 | J8: =IFERROR( IF(SK[[#This Row],[GEREKLİ ADET]]=1, SK[[#This Row],[BOY]]-SK[[#This Row],[KESİLECEK PARÇA ADEDİ ]]*(SK[[#This Row],[KESİLECEK PARÇA BOYU]]+$O$2), IF( MOD(SK[[#This Row],[BOY]],SK[[#This Row],[KESİLECEK PARÇA BOYU]])-$O$2*INT(SK[[#This Row],[BOY]]/SK[[#This Row],[KESİLECEK PARÇA BOYU]])>$P$2, (MOD(SK[[#This Row],[BOY]],SK[[#This Row],[KESİLECEK PARÇA BOYU]])-$O$2*INT(SK[[#This Row],[BOY]]/SK[[#This Row],[KESİLECEK PARÇA BOYU]]))*SK[[#This Row],[GEREKLİ ADET]], 0 ) ) + IF(SK[[#This Row],[GEREKLİ ADET]]>1, IF( INT((SK[[#This Row],[BOY]]+$O$2)/(SK[[#This Row],[KESİLECEK PARÇA BOYU]]+$O$2))=0, 0, IF( (SK[[#This Row],[BOY]]-MOD(SK[[#This Row],[KESİLECEK PARÇA ADEDİ ]], INT((SK[[#This Row],[BOY]]+$O$2)/(SK[[#This Row],[KESİLECEK PARÇA BOYU]]+$O$2)) )*(SK[[#This Row],[KESİLECEK PARÇA BOYU]]+$O$2))>$P$2, IF( MOD(SK[[#This Row],[KESİLECEK PARÇA ADEDİ ]], INT((SK[[#This Row],[BOY]]+$O$2)/(SK[[#This Row],[KESİLECEK PARÇA BOYU]]+$O$2)))=0, 0, SK[[#This Row],[BOY]]-MOD(SK[[#This Row],[KESİLECEK PARÇA ADEDİ ]], INT((SK[[#This Row],[BOY]]+$O$2)/(SK[[#This Row],[KESİLECEK PARÇA BOYU]]+$O$2)))*(SK[[#This Row],[KESİLECEK PARÇA BOYU]]+$O$2) ), 0 ) ), 0 ), 0) -> 0 | K8: =IFERROR( IF( IF( MOD(SK[[#This Row],[BOY]],SK[[#This Row],[KESİLECEK PARÇA BOYU]])-$O$2*INT(SK[[#This Row],[BOY]]/SK[[#This Row],[KESİLECEK PARÇA BOYU]])>$P$2, (MOD(SK[[#This Row],[BOY]],SK[[#This Row],[KESİLECEK PARÇA BOYU]])-$O$2*INT(SK[[#This Row],[BOY]]/SK[[#This Row],[KESİLECEK PARÇA BOYU]])), 0 )>0,IF( MOD(SK[[#This Row],[BOY]],SK[[#This Row],[KESİLECEK PARÇA BOYU]])-$O$2*INT(SK[[#This Row],[BOY]]/SK[[#This Row],[KESİLECEK PARÇA BOYU]])>$P$2, (MOD(SK[[#This Row],[BOY]],SK[[#This Row],[KESİLECEK PARÇA BOYU]])-$O$2*INT(SK[[#This Row],[BOY]]/SK[[#This Row],[KESİLECEK PARÇA BOYU]])), 0 ),0),0) -> 0 | L8: =IFERROR(IF(SK[[#This Row],[BOY]]-(SK[[#This Row],[KESİLECEK PARÇA BOYU]]+$O$2)*MOD(SK[[#This Row],[KESİLECEK PARÇA ADEDİ ]],INT(SK[[#This Row],[BOY]]/(SK[[#This Row],[KESİLECEK PARÇA BOYU]]+$O$2)))<SK[[#This Row],[BOY]],SK[[#This Row],[BOY]]-(SK[[#This Row],[KESİLECEK PARÇA BOYU]]+$O$2)*MOD(SK[[#This Row],[KESİLECEK PARÇA ADEDİ ]],INT(SK[[#This Row],[BOY]]/(SK[[#This Row],[KESİLECEK PARÇA BOYU]]+$O$2))),0),0) -> 0 | XEZ8: NPI PROFİL
H9: =IFERROR(IF( SK[[#This Row],[KESİLECEK PARÇA ADEDİ ]]*SK[[#This Row],[KESİLECEK PARÇA BOYU]] < SK[[#This Row],[BOY]] - 3*ROUNDUP(SK[[#This Row],[BOY]]/SK[[#This Row],[KESİLECEK PARÇA BOYU]] - 1, 0), 1, ROUNDUP(SK[[#This Row],[KESİLECEK PARÇA ADEDİ ]]/INT(SK[[#This Row],[BOY]]/(SK[[#This Row],[KESİLECEK PARÇA BOYU]]+$O$2)), 0) ),0) -> 0 | I9: 12000 | J9: =IFERROR( IF(SK[[#This Row],[GEREKLİ ADET]]=1, SK[[#This Row],[BOY]]-SK[[#This Row],[KESİLECEK PARÇA ADEDİ ]]*(SK[[#This Row],[KESİLECEK PARÇA BOYU]]+$O$2), IF( MOD(SK[[#This Row],[BOY]],SK[[#This Row],[KESİLECEK PARÇA BOYU]])-$O$2*INT(SK[[#This Row],[BOY]]/SK[[#This Row],[KESİLECEK PARÇA BOYU]])>$P$2, (MOD(SK[[#This Row],[BOY]],SK[[#This Row],[KESİLECEK PARÇA BOYU]])-$O$2*INT(SK[[#This Row],[BOY]]/SK[[#This Row],[KESİLECEK PARÇA BOYU]]))*SK[[#This Row],[GEREKLİ ADET]], 0 ) ) + IF(SK[[#This Row],[GEREKLİ ADET]]>1, IF( INT((SK[[#This Row],[BOY]]+$O$2)/(SK[[#This Row],[KESİLECEK PARÇA BOYU]]+$O$2))=0, 0, IF( (SK[[#This Row],[BOY]]-MOD(SK[[#This Row],[KESİLECEK PARÇA ADEDİ ]], INT((SK[[#This Row],[BOY]]+$O$2)/(SK[[#This Row],[KESİLECEK PARÇA BOYU]]+$O$2)) )*(SK[[#This Row],[KESİLECEK PARÇA BOYU]]+$O$2))>$P$2, IF( MOD(SK[[#This Row],[KESİLECEK PARÇA ADEDİ ]], INT((SK[[#This Row],[BOY]]+$O$2)/(SK[[#This Row],[KESİLECEK PARÇA BOYU]]+$O$2)))=0, 0, SK[[#This Row],[BOY]]-MOD(SK[[#This Row],[KESİLECEK PARÇA ADEDİ ]], INT((SK[[#This Row],[BOY]]+$O$2)/(SK[[#This Row],[KESİLECEK PARÇA BOYU]]+$O$2)))*(SK[[#This Row],[KESİLECEK PARÇA BOYU]]+$O$2) ), 0 ) ), 0 ), 0) -> 0 | K9: =IFERROR( IF( IF( MOD(SK[[#This Row],[BOY]],SK[[#This Row],[KESİLECEK PARÇA BOYU]])-$O$2*INT(SK[[#This Row],[BOY]]/SK[[#This Row],[KESİLECEK PARÇA BOYU]])>$P$2, (MOD(SK[[#This Row],[BOY]],SK[[#This Row],[KESİLECEK PARÇA BOYU]])-$O$2*INT(SK[[#This Row],[BOY]]/SK[[#This Row],[KESİLECEK PARÇA BOYU]])), 0 )>0,IF( MOD(SK[[#This Row],[BOY]],SK[[#This Row],[KESİLECEK PARÇA BOYU]])-$O$2*INT(SK[[#This Row],[BOY]]/SK[[#This Row],[KESİLECEK PARÇA BOYU]])>$P$2, (MOD(SK[[#This Row],[BOY]],SK[[#This Row],[KESİLECEK PARÇA BOYU]])-$O$2*INT(SK[[#This Row],[BOY]]/SK[[#This Row],[KESİLECEK PARÇA BOYU]])), 0 ),0),0) -> 0 | L9: =IFERROR(IF(SK[[#This Row],[BOY]]-(SK[[#This Row],[KESİLECEK PARÇA BOYU]]+$O$2)*MOD(SK[[#This Row],[KESİLECEK PARÇA ADEDİ ]],INT(SK[[#This Row],[BOY]]/(SK[[#This Row],[KESİLECEK PARÇA BOYU]]+$O$2)))<SK[[#This Row],[BOY]],SK[[#This Row],[BOY]]-(SK[[#This Row],[KESİLECEK PARÇA BOYU]]+$O$2)*MOD(SK[[#This Row],[KESİLECEK PARÇA ADEDİ ]],INT(SK[[#This Row],[BOY]]/(SK[[#This Row],[KESİLECEK PARÇA BOYU]]+$O$2))),0),0) -> 0 | XEZ9: Ø PROFİL
H10: =IFERROR(IF( SK[[#This Row],[KESİLECEK PARÇA ADEDİ ]]*SK[[#This Row],[KESİLECEK PARÇA BOYU]] < SK[[#This Row],[BOY]] - 3*ROUNDUP(SK[[#This Row],[BOY]]/SK[[#This Row],[KESİLECEK PARÇA BOYU]] - 1, 0), 1, ROUNDUP(SK[[#This Row],[KESİLECEK PARÇA ADEDİ ]]/INT(SK[[#This Row],[BOY]]/(SK[[#This Row],[KESİLECEK PARÇA BOYU]]+$O$2)), 0) ),0) -> 0 | I10: 12000 | J10: =IFERROR( IF(SK[[#This Row],[GEREKLİ ADET]]=1, SK[[#This Row],[BOY]]-SK[[#This Row],[KESİLECEK PARÇA ADEDİ ]]*(SK[[#This Row],[KESİLECEK PARÇA BOYU]]+$O$2), IF( MOD(SK[[#This Row],[BOY]],SK[[#This Row],[KESİLECEK PARÇA BOYU]])-$O$2*INT(SK[[#This Row],[BOY]]/SK[[#This Row],[KESİLECEK PARÇA BOYU]])>$P$2, (MOD(SK[[#This Row],[BOY]],SK[[#This Row],[KESİLECEK PARÇA BOYU]])-$O$2*INT(SK[[#This Row],[BOY]]/SK[[#This Row],[KESİLECEK PARÇA BOYU]]))*SK[[#This Row],[GEREKLİ ADET]], 0 ) ) + IF(SK[[#This Row],[GEREKLİ ADET]]>1, IF( INT((SK[[#This Row],[BOY]]+$O$2)/(SK[[#This Row],[KESİLECEK PARÇA BOYU]]+$O$2))=0, 0, IF( (SK[[#This Row],[BOY]]-MOD(SK[[#This Row],[KESİLECEK PARÇA ADEDİ ]], INT((SK[[#This Row],[BOY]]+$O$2)/(SK[[#This Row],[KESİLECEK PARÇA BOYU]]+$O$2)) )*(SK[[#This Row],[KESİLECEK PARÇA BOYU]]+$O$2))>$P$2, IF( MOD(SK[[#This Row],[KESİLECEK PARÇA ADEDİ ]], INT((SK[[#This Row],[BOY]]+$O$2)/(SK[[#This Row],[KESİLECEK PARÇA BOYU]]+$O$2)))=0, 0, SK[[#This Row],[BOY]]-MOD(SK[[#This Row],[KESİLECEK PARÇA ADEDİ ]], INT((SK[[#This Row],[BOY]]+$O$2)/(SK[[#This Row],[KESİLECEK PARÇA BOYU]]+$O$2)))*(SK[[#This Row],[KESİLECEK PARÇA BOYU]]+$O$2) ), 0 ) ), 0 ), 0) -> 0 | K10: =IFERROR( IF( IF( MOD(SK[[#This Row],[BOY]],SK[[#This Row],[KESİLECEK PARÇA BOYU]])-$O$2*INT(SK[[#This Row],[BOY]]/SK[[#This Row],[KESİLECEK PARÇA BOYU]])>$P$2, (MOD(SK[[#This Row],[BOY]],SK[[#This Row],[KESİLECEK PARÇA BOYU]])-$O$2*INT(SK[[#This Row],[BOY]]/SK[[#This Row],[KESİLECEK PARÇA BOYU]])), 0 )>0,IF( MOD(SK[[#This Row],[BOY]],SK[[#This Row],[KESİLECEK PARÇA BOYU]])-$O$2*INT(SK[[#This Row],[BOY]]/SK[[#This Row],[KESİLECEK PARÇA BOYU]])>$P$2, (MOD(SK[[#This Row],[BOY]],SK[[#This Row],[KESİLECEK PARÇA BOYU]])-$O$2*INT(SK[[#This Row],[BOY]]/SK[[#This Row],[KESİLECEK PARÇA BOYU]])), 0 ),0),0) -> 0 | L10: =IFERROR(IF(SK[[#This Row],[BOY]]-(SK[[#This Row],[KESİLECEK PARÇA BOYU]]+$O$2)*MOD(SK[[#This Row],[KESİLECEK PARÇA ADEDİ ]],INT(SK[[#This Row],[BOY]]/(SK[[#This Row],[KESİLECEK PARÇA BOYU]]+$O$2)))<SK[[#This Row],[BOY]],SK[[#This Row],[BOY]]-(SK[[#This Row],[KESİLECEK PARÇA BOYU]]+$O$2)*MOD(SK[[#This Row],[KESİLECEK PARÇA ADEDİ ]],INT(SK[[#This Row],[BOY]]/(SK[[#This Row],[KESİLECEK PARÇA BOYU]]+$O$2))),0),0) -> 0 | XEZ10: KARE DOLU
H11: =IFERROR(IF( SK[[#This Row],[KESİLECEK PARÇA ADEDİ ]]*SK[[#This Row],[KESİLECEK PARÇA BOYU]] < SK[[#This Row],[BOY]] - 3*ROUNDUP(SK[[#This Row],[BOY]]/SK[[#This Row],[KESİLECEK PARÇA BOYU]] - 1, 0), 1, ROUNDUP(SK[[#This Row],[KESİLECEK PARÇA ADEDİ ]]/INT(SK[[#This Row],[BOY]]/(SK[[#This Row],[KESİLECEK PARÇA BOYU]]+$O$2)), 0) ),0) -> 0 | J11: =IFERROR( IF(SK[[#This Row],[GEREKLİ ADET]]=1, SK[[#This Row],[BOY]]-SK[[#This Row],[KESİLECEK PARÇA ADEDİ ]]*(SK[[#This Row],[KESİLECEK PARÇA BOYU]]+$O$2), IF( MOD(SK[[#This Row],[BOY]],SK[[#This Row],[KESİLECEK PARÇA BOYU]])-$O$2*INT(SK[[#This Row],[BOY]]/SK[[#This Row],[KESİLECEK PARÇA BOYU]])>$P$2, (MOD(SK[[#This Row],[BOY]],SK[[#This Row],[KESİLECEK PARÇA BOYU]])-$O$2*INT(SK[[#This Row],[BOY]]/SK[[#This Row],[KESİLECEK PARÇA BOYU]]))*SK[[#This Row],[GEREKLİ ADET]], 0 ) ) + IF(SK[[#This Row],[GEREKLİ ADET]]>1, IF( INT((SK[[#This Row],[BOY]]+$O$2)/(SK[[#This Row],[KESİLECEK PARÇA BOYU]]+$O$2))=0, 0, IF( (SK[[#This Row],[BOY]]-MOD(SK[[#This Row],[KESİLECEK PARÇA ADEDİ ]], INT((SK[[#This Row],[BOY]]+$O$2)/(SK[[#This Row],[KESİLECEK PARÇA BOYU]]+$O$2)) )*(SK[[#This Row],[KESİLECEK PARÇA BOYU]]+$O$2))>$P$2, IF( MOD(SK[[#This Row],[KESİLECEK PARÇA ADEDİ ]], INT((SK[[#This Row],[BOY]]+$O$2)/(SK[[#This Row],[KESİLECEK PARÇA BOYU]]+$O$2)))=0, 0, SK[[#This Row],[BOY]]-MOD(SK[[#This Row],[KESİLECEK PARÇA ADEDİ ]], INT((SK[[#This Row],[BOY]]+$O$2)/(SK[[#This Row],[KESİLECEK PARÇA BOYU]]+$O$2)))*(SK[[#This Row],[KESİLECEK PARÇA BOYU]]+$O$2) ), 0 ) ), 0 ), 0) -> 0 | K11: =IFERROR( IF( IF( MOD(SK[[#This Row],[BOY]],SK[[#This Row],[KESİLECEK PARÇA BOYU]])-$O$2*INT(SK[[#This Row],[BOY]]/SK[[#This Row],[KESİLECEK PARÇA BOYU]])>$P$2, (MOD(SK[[#This Row],[BOY]],SK[[#This Row],[KESİLECEK PARÇA BOYU]])-$O$2*INT(SK[[#This Row],[BOY]]/SK[[#This Row],[KESİLECEK PARÇA BOYU]])), 0 )>0,IF( MOD(SK[[#This Row],[BOY]],SK[[#This Row],[KESİLECEK PARÇA BOYU]])-$O$2*INT(SK[[#This Row],[BOY]]/SK[[#This Row],[KESİLECEK PARÇA BOYU]])>$P$2, (MOD(SK[[#This Row],[BOY]],SK[[#This Row],[KESİLECEK PARÇA BOYU]])-$O$2*INT(SK[[#This Row],[BOY]]/SK[[#This Row],[KESİLECEK PARÇA BOYU]])), 0 ),0),0) -> 0 | L11: =IFERROR(IF(SK[[#This Row],[BOY]]-(SK[[#This Row],[KESİLECEK PARÇA BOYU]]+$O$2)*MOD(SK[[#This Row],[KESİLECEK PARÇA ADEDİ ]],INT(SK[[#This Row],[BOY]]/(SK[[#This Row],[KESİLECEK PARÇA BOYU]]+$O$2)))<SK[[#This Row],[BOY]],SK[[#This Row],[BOY]]-(SK[[#This Row],[KESİLECEK PARÇA BOYU]]+$O$2)*MOD(SK[[#This Row],[KESİLECEK PARÇA ADEDİ ]],INT(SK[[#This Row],[BOY]]/(SK[[#This Row],[KESİLECEK PARÇA BOYU]]+$O$2))),0),0) -> 0
H12: =IFERROR(IF( SK[[#This Row],[KESİLECEK PARÇA ADEDİ ]]*SK[[#This Row],[KESİLECEK PARÇA BOYU]] < SK[[#This Row],[BOY]] - 3*ROUNDUP(SK[[#This Row],[BOY]]/SK[[#This Row],[KESİLECEK PARÇA BOYU]] - 1, 0), 1, ROUNDUP(SK[[#This Row],[KESİLECEK PARÇA ADEDİ ]]/INT(SK[[#This Row],[BOY]]/(SK[[#This Row],[KESİLECEK PARÇA BOYU]]+$O$2)), 0) ),0) -> 0 | I12: 6000 | J12: =IFERROR( IF(SK[[#This Row],[GEREKLİ ADET]]=1, SK[[#This Row],[BOY]]-SK[[#This Row],[KESİLECEK PARÇA ADEDİ ]]*(SK[[#This Row],[KESİLECEK PARÇA BOYU]]+$O$2), IF( MOD(SK[[#This Row],[BOY]],SK[[#This Row],[KESİLECEK PARÇA BOYU]])-$O$2*INT(SK[[#This Row],[BOY]]/SK[[#This Row],[KESİLECEK PARÇA BOYU]])>$P$2, (MOD(SK[[#This Row],[BOY]],SK[[#This Row],[KESİLECEK PARÇA BOYU]])-$O$2*INT(SK[[#This Row],[BOY]]/SK[[#This Row],[KESİLECEK PARÇA BOYU]]))*SK[[#This Row],[GEREKLİ ADET]], 0 ) ) + IF(SK[[#This Row],[GEREKLİ ADET]]>1, IF( INT((SK[[#This Row],[BOY]]+$O$2)/(SK[[#This Row],[KESİLECEK PARÇA BOYU]]+$O$2))=0, 0, IF( (SK[[#This Row],[BOY]]-MOD(SK[[#This Row],[KESİLECEK PARÇA ADEDİ ]], INT((SK[[#This Row],[BOY]]+$O$2)/(SK[[#This Row],[KESİLECEK PARÇA BOYU]]+$O$2)) )*(SK[[#This Row],[KESİLECEK PARÇA BOYU]]+$O$2))>$P$2, IF( MOD(SK[[#This Row],[KESİLECEK PARÇA ADEDİ ]], INT((SK[[#This Row],[BOY]]+$O$2)/(SK[[#This Row],[KESİLECEK PARÇA BOYU]]+$O$2)))=0, 0, SK[[#This Row],[BOY]]-MOD(SK[[#This Row],[KESİLECEK PARÇA ADEDİ ]], INT((SK[[#This Row],[BOY]]+$O$2)/(SK[[#This Row],[KESİLECEK PARÇA BOYU]]+$O$2)))*(SK[[#This Row],[KESİLECEK PARÇA BOYU]]+$O$2) ), 0 ) ), 0 ), 0) -> 0 | K12: =IFERROR( IF( IF( MOD(SK[[#This Row],[BOY]],SK[[#This Row],[KESİLECEK PARÇA BOYU]])-$O$2*INT(SK[[#This Row],[BOY]]/SK[[#This Row],[KESİLECEK PARÇA BOYU]])>$P$2, (MOD(SK[[#This Row],[BOY]],SK[[#This Row],[KESİLECEK PARÇA BOYU]])-$O$2*INT(SK[[#This Row],[BOY]]/SK[[#This Row],[KESİLECEK PARÇA BOYU]])), 0 )>0,IF( MOD(SK[[#This Row],[BOY]],SK[[#This Row],[KESİLECEK PARÇA BOYU]])-$O$2*INT(SK[[#This Row],[BOY]]/SK[[#This Row],[KESİLECEK PARÇA BOYU]])>$P$2, (MOD(SK[[#This Row],[BOY]],SK[[#This Row],[KESİLECEK PARÇA BOYU]])-$O$2*INT(SK[[#This Row],[BOY]]/SK[[#This Row],[KESİLECEK PARÇA BOYU]])), 0 ),0),0) -> 0 | L12: =IFERROR(IF(SK[[#This Row],[BOY]]-(SK[[#This Row],[KESİLECEK PARÇA BOYU]]+$O$2)*MOD(SK[[#This Row],[KESİLECEK PARÇA ADEDİ ]],INT(SK[[#This Row],[BOY]]/(SK[[#This Row],[KESİLECEK PARÇA BOYU]]+$O$2)))<SK[[#This Row],[BOY]],SK[[#This Row],[BOY]]-(SK[[#This Row],[KESİLECEK PARÇA BOYU]]+$O$2)*MOD(SK[[#This Row],[KESİLECEK PARÇA ADEDİ ]],INT(SK[[#This Row],[BOY]]/(SK[[#This Row],[KESİLECEK PARÇA BOYU]]+$O$2))),0),0) -> 0
H13: =IFERROR(IF( SK[[#This Row],[KESİLECEK PARÇA ADEDİ ]]*SK[[#This Row],[KESİLECEK PARÇA BOYU]] < SK[[#This Row],[BOY]] - 3*ROUNDUP(SK[[#This Row],[BOY]]/SK[[#This Row],[KESİLECEK PARÇA BOYU]] - 1, 0), 1, ROUNDUP(SK[[#This Row],[KESİLECEK PARÇA ADEDİ ]]/INT(SK[[#This Row],[BOY]]/(SK[[#This Row],[KESİLECEK PARÇA BOYU]]+$O$2)), 0) ),0) -> 0 | J13: =IFERROR( IF(SK[[#This Row],[GEREKLİ ADET]]=1, SK[[#This Row],[BOY]]-SK[[#This Row],[KESİLECEK PARÇA ADEDİ ]]*(SK[[#This Row],[KESİLECEK PARÇA BOYU]]+$O$2), IF( MOD(SK[[#This Row],[BOY]],SK[[#This Row],[KESİLECEK PARÇA BOYU]])-$O$2*INT(SK[[#This Row],[BOY]]/SK[[#This Row],[KESİLECEK PARÇA BOYU]])>$P$2, (MOD(SK[[#This Row],[BOY]],SK[[#This Row],[KESİLECEK PARÇA BOYU]])-$O$2*INT(SK[[#This Row],[BOY]]/SK[[#This Row],[KESİLECEK PARÇA BOYU]]))*SK[[#This Row],[GEREKLİ ADET]], 0 ) ) + IF(SK[[#This Row],[GEREKLİ ADET]]>1, IF( INT((SK[[#This Row],[BOY]]+$O$2)/(SK[[#This Row],[KESİLECEK PARÇA BOYU]]+$O$2))=0, 0, IF( (SK[[#This Row],[BOY]]-MOD(SK[[#This Row],[KESİLECEK PARÇA ADEDİ ]], INT((SK[[#This Row],[BOY]]+$O$2)/(SK[[#This Row],[KESİLECEK PARÇA BOYU]]+$O$2)) )*(SK[[#This Row],[KESİLECEK PARÇA BOYU]]+$O$2))>$P$2, IF( MOD(SK[[#This Row],[KESİLECEK PARÇA ADEDİ ]], INT((SK[[#This Row],[BOY]]+$O$2)/(SK[[#This Row],[KESİLECEK PARÇA BOYU]]+$O$2)))=0, 0, SK[[#This Row],[BOY]]-MOD(SK[[#This Row],[KESİLECEK PARÇA ADEDİ ]], INT((SK[[#This Row],[BOY]]+$O$2)/(SK[[#This Row],[KESİLECEK PARÇA BOYU]]+$O$2)))*(SK[[#This Row],[KESİLECEK PARÇA BOYU]]+$O$2) ), 0 ) ), 0 ), 0) -> 0 | K13: =IFERROR( IF( IF( MOD(SK[[#This Row],[BOY]],SK[[#This Row],[KESİLECEK PARÇA BOYU]])-$O$2*INT(SK[[#This Row],[BOY]]/SK[[#This Row],[KESİLECEK PARÇA BOYU]])>$P$2, (MOD(SK[[#This Row],[BOY]],SK[[#This Row],[KESİLECEK PARÇA BOYU]])-$O$2*INT(SK[[#This Row],[BOY]]/SK[[#This Row],[KESİLECEK PARÇA BOYU]])), 0 )>0,IF( MOD(SK[[#This Row],[BOY]],SK[[#This Row],[KESİLECEK PARÇA BOYU]])-$O$2*INT(SK[[#This Row],[BOY]]/SK[[#This Row],[KESİLECEK PARÇA BOYU]])>$P$2, (MOD(SK[[#This Row],[BOY]],SK[[#This Row],[KESİLECEK PARÇA BOYU]])-$O$2*INT(SK[[#This Row],[BOY]]/SK[[#This Row],[KESİLECEK PARÇA BOYU]])), 0 ),0),0) -> 0 | L13: =IFERROR(IF(SK[[#This Row],[BOY]]-(SK[[#This Row],[KESİLECEK PARÇA BOYU]]+$O$2)*MOD(SK[[#This Row],[KESİLECEK PARÇA ADEDİ ]],INT(SK[[#This Row],[BOY]]/(SK[[#This Row],[KESİLECEK PARÇA BOYU]]+$O$2)))<SK[[#This Row],[BOY]],SK[[#This Row],[BOY]]-(SK[[#This Row],[KESİLECEK PARÇA BOYU]]+$O$2)*MOD(SK[[#This Row],[KESİLECEK PARÇA ADEDİ ]],INT(SK[[#This Row],[BOY]]/(SK[[#This Row],[KESİLECEK PARÇA BOYU]]+$O$2))),0),0) -> 0
H14: =IFERROR(IF( SK[[#This Row],[KESİLECEK PARÇA ADEDİ ]]*SK[[#This Row],[KESİLECEK PARÇA BOYU]] < SK[[#This Row],[BOY]] - 3*ROUNDUP(SK[[#This Row],[BOY]]/SK[[#This Row],[KESİLECEK PARÇA BOYU]] - 1, 0), 1, ROUNDUP(SK[[#This Row],[KESİLECEK PARÇA ADEDİ ]]/INT(SK[[#This Row],[BOY]]/(SK[[#This Row],[KESİLECEK PARÇA BOYU]]+$O$2)), 0) ),0) -> 0 | J14: =IFERROR( IF(SK[[#This Row],[GEREKLİ ADET]]=1, SK[[#This Row],[BOY]]-SK[[#This Row],[KESİLECEK PARÇA ADEDİ ]]*(SK[[#This Row],[KESİLECEK PARÇA BOYU]]+$O$2), IF( MOD(SK[[#This Row],[BOY]],SK[[#This Row],[KESİLECEK PARÇA BOYU]])-$O$2*INT(SK[[#This Row],[BOY]]/SK[[#This Row],[KESİLECEK PARÇA BOYU]])>$P$2, (MOD(SK[[#This Row],[BOY]],SK[[#This Row],[KESİLECEK PARÇA BOYU]])-$O$2*INT(SK[[#This Row],[BOY]]/SK[[#This Row],[KESİLECEK PARÇA BOYU]]))*SK[[#This Row],[GEREKLİ ADET]], 0 ) ) + IF(SK[[#This Row],[GEREKLİ ADET]]>1, IF( INT((SK[[#This Row],[BOY]]+$O$2)/(SK[[#This Row],[KESİLECEK PARÇA BOYU]]+$O$2))=0, 0, IF( (SK[[#This Row],[BOY]]-MOD(SK[[#This Row],[KESİLECEK PARÇA ADEDİ ]], INT((SK[[#This Row],[BOY]]+$O$2)/(SK[[#This Row],[KESİLECEK PARÇA BOYU]]+$O$2)) )*(SK[[#This Row],[KESİLECEK PARÇA BOYU]]+$O$2))>$P$2, IF( MOD(SK[[#This Row],[KESİLECEK PARÇA ADEDİ ]], INT((SK[[#This Row],[BOY]]+$O$2)/(SK[[#This Row],[KESİLECEK PARÇA BOYU]]+$O$2)))=0, 0, SK[[#This Row],[BOY]]-MOD(SK[[#This Row],[KESİLECEK PARÇA ADEDİ ]], INT((SK[[#This Row],[BOY]]+$O$2)/(SK[[#This Row],[KESİLECEK PARÇA BOYU]]+$O$2)))*(SK[[#This Row],[KESİLECEK PARÇA BOYU]]+$O$2) ), 0 ) ), 0 ), 0) -> 0 | K14: =IFERROR( IF( IF( MOD(SK[[#This Row],[BOY]],SK[[#This Row],[KESİLECEK PARÇA BOYU]])-$O$2*INT(SK[[#This Row],[BOY]]/SK[[#This Row],[KESİLECEK PARÇA BOYU]])>$P$2, (MOD(SK[[#This Row],[BOY]],SK[[#This Row],[KESİLECEK PARÇA BOYU]])-$O$2*INT(SK[[#This Row],[BOY]]/SK[[#This Row],[KESİLECEK PARÇA BOYU]])), 0 )>0,IF( MOD(SK[[#This Row],[BOY]],SK[[#This Row],[KESİLECEK PARÇA BOYU]])-$O$2*INT(SK[[#This Row],[BOY]]/SK[[#This Row],[KESİLECEK PARÇA BOYU]])>$P$2, (MOD(SK[[#This Row],[BOY]],SK[[#This Row],[KESİLECEK PARÇA BOYU]])-$O$2*INT(SK[[#This Row],[BOY]]/SK[[#This Row],[KESİLECEK PARÇA BOYU]])), 0 ),0),0) -> 0 | L14: =IFERROR(IF(SK[[#This Row],[BOY]]-(SK[[#This Row],[KESİLECEK PARÇA BOYU]]+$O$2)*MOD(SK[[#This Row],[KESİLECEK PARÇA ADEDİ ]],INT(SK[[#This Row],[BOY]]/(SK[[#This Row],[KESİLECEK PARÇA BOYU]]+$O$2)))<SK[[#This Row],[BOY]],SK[[#This Row],[BOY]]-(SK[[#This Row],[KESİLECEK PARÇA BOYU]]+$O$2)*MOD(SK[[#This Row],[KESİLECEK PARÇA ADEDİ ]],INT(SK[[#This Row],[BOY]]/(SK[[#This Row],[KESİLECEK PARÇA BOYU]]+$O$2))),0),0) -> 0
H15: =IFERROR(IF( SK[[#This Row],[KESİLECEK PARÇA ADEDİ ]]*SK[[#This Row],[KESİLECEK PARÇA BOYU]] < SK[[#This Row],[BOY]] - 3*ROUNDUP(SK[[#This Row],[BOY]]/SK[[#This Row],[KESİLECEK PARÇA BOYU]] - 1, 0), 1, ROUNDUP(SK[[#This Row],[KESİLECEK PARÇA ADEDİ ]]/INT(SK[[#This Row],[BOY]]/(SK[[#This Row],[KESİLECEK PARÇA BOYU]]+$O$2)), 0) ),0) -> 0 | I15: 12000 | J15: =IFERROR( IF(SK[[#This Row],[GEREKLİ ADET]]=1, SK[[#This Row],[BOY]]-SK[[#This Row],[KESİLECEK PARÇA ADEDİ ]]*(SK[[#This Row],[KESİLECEK PARÇA BOYU]]+$O$2), IF( MOD(SK[[#This Row],[BOY]],SK[[#This Row],[KESİLECEK PARÇA BOYU]])-$O$2*INT(SK[[#This Row],[BOY]]/SK[[#This Row],[KESİLECEK PARÇA BOYU]])>$P$2, (MOD(SK[[#This Row],[BOY]],SK[[#This Row],[KESİLECEK PARÇA BOYU]])-$O$2*INT(SK[[#This Row],[BOY]]/SK[[#This Row],[KESİLECEK PARÇA BOYU]]))*SK[[#This Row],[GEREKLİ ADET]], 0 ) ) + IF(SK[[#This Row],[GEREKLİ ADET]]>1, IF( INT((SK[[#This Row],[BOY]]+$O$2)/(SK[[#This Row],[KESİLECEK PARÇA BOYU]]+$O$2))=0, 0, IF( (SK[[#This Row],[BOY]]-MOD(SK[[#This Row],[KESİLECEK PARÇA ADEDİ ]], INT((SK[[#This Row],[BOY]]+$O$2)/(SK[[#This Row],[KESİLECEK PARÇA BOYU]]+$O$2)) )*(SK[[#This Row],[KESİLECEK PARÇA BOYU]]+$O$2))>$P$2, IF( MOD(SK[[#This Row],[KESİLECEK PARÇA ADEDİ ]], INT((SK[[#This Row],[BOY]]+$O$2)/(SK[[#This Row],[KESİLECEK PARÇA BOYU]]+$O$2)))=0, 0, SK[[#This Row],[BOY]]-MOD(SK[[#This Row],[KESİLECEK PARÇA ADEDİ ]], INT((SK[[#This Row],[BOY]]+$O$2)/(SK[[#This Row],[KESİLECEK PARÇA BOYU]]+$O$2)))*(SK[[#This Row],[KESİLECEK PARÇA BOYU]]+$O$2) ), 0 ) ), 0 ), 0) -> 0 | K15: =IFERROR( IF( IF( MOD(SK[[#This Row],[BOY]],SK[[#This Row],[KESİLECEK PARÇA BOYU]])-$O$2*INT(SK[[#This Row],[BOY]]/SK[[#This Row],[KESİLECEK PARÇA BOYU]])>$P$2, (MOD(SK[[#This Row],[BOY]],SK[[#This Row],[KESİLECEK PARÇA BOYU]])-$O$2*INT(SK[[#This Row],[BOY]]/SK[[#This Row],[KESİLECEK PARÇA BOYU]])), 0 )>0,IF( MOD(SK[[#This Row],[BOY]],SK[[#This Row],[KESİLECEK PARÇA BOYU]])-$O$2*INT(SK[[#This Row],[BOY]]/SK[[#This Row],[KESİLECEK PARÇA BOYU]])>$P$2, (MOD(SK[[#This Row],[BOY]],SK[[#This Row],[KESİLECEK PARÇA BOYU]])-$O$2*INT(SK[[#This Row],[BOY]]/SK[[#This Row],[KESİLECEK PARÇA BOYU]])), 0 ),0),0) -> 0 | L15: =IFERROR(IF(SK[[#This Row],[BOY]]-(SK[[#This Row],[KESİLECEK PARÇA BOYU]]+$O$2)*MOD(SK[[#This Row],[KESİLECEK PARÇA ADEDİ ]],INT(SK[[#This Row],[BOY]]/(SK[[#This Row],[KESİLECEK PARÇA BOYU]]+$O$2)))<SK[[#This Row],[BOY]],SK[[#This Row],[BOY]]-(SK[[#This Row],[KESİLECEK PARÇA BOYU]]+$O$2)*MOD(SK[[#This Row],[KESİLECEK PARÇA ADEDİ ]],INT(SK[[#This Row],[BOY]]/(SK[[#This Row],[KESİLECEK PARÇA BOYU]]+$O$2))),0),0) -> 0
H16: =IFERROR(IF( SK[[#This Row],[KESİLECEK PARÇA ADEDİ ]]*SK[[#This Row],[KESİLECEK PARÇA BOYU]] < SK[[#This Row],[BOY]] - 3*ROUNDUP(SK[[#This Row],[BOY]]/SK[[#This Row],[KESİLECEK PARÇA BOYU]] - 1, 0), 1, ROUNDUP(SK[[#This Row],[KESİLECEK PARÇA ADEDİ ]]/INT(SK[[#This Row],[BOY]]/(SK[[#This Row],[KESİLECEK PARÇA BOYU]]+$O$2)), 0) ),0) -> 0 | J16: =IFERROR( IF(SK[[#This Row],[GEREKLİ ADET]]=1, SK[[#This Row],[BOY]]-SK[[#This Row],[KESİLECEK PARÇA ADEDİ ]]*(SK[[#This Row],[KESİLECEK PARÇA BOYU]]+$O$2), IF( MOD(SK[[#This Row],[BOY]],SK[[#This Row],[KESİLECEK PARÇA BOYU]])-$O$2*INT(SK[[#This Row],[BOY]]/SK[[#This Row],[KESİLECEK PARÇA BOYU]])>$P$2, (MOD(SK[[#This Row],[BOY]],SK[[#This Row],[KESİLECEK PARÇA BOYU]])-$O$2*INT(SK[[#This Row],[BOY]]/SK[[#This Row],[KESİLECEK PARÇA BOYU]]))*SK[[#This Row],[GEREKLİ ADET]], 0 ) ) + IF(SK[[#This Row],[GEREKLİ ADET]]>1, IF( INT((SK[[#This Row],[BOY]]+$O$2)/(SK[[#This Row],[KESİLECEK PARÇA BOYU]]+$O$2))=0, 0, IF( (SK[[#This Row],[BOY]]-MOD(SK[[#This Row],[KESİLECEK PARÇA ADEDİ ]], INT((SK[[#This Row],[BOY]]+$O$2)/(SK[[#This Row],[KESİLECEK PARÇA BOYU]]+$O$2)) )*(SK[[#This Row],[KESİLECEK PARÇA BOYU]]+$O$2))>$P$2, IF( MOD(SK[[#This Row],[KESİLECEK PARÇA ADEDİ ]], INT((SK[[#This Row],[BOY]]+$O$2)/(SK[[#This Row],[KESİLECEK PARÇA BOYU]]+$O$2)))=0, 0, SK[[#This Row],[BOY]]-MOD(SK[[#This Row],[KESİLECEK PARÇA ADEDİ ]], INT((SK[[#This Row],[BOY]]+$O$2)/(SK[[#This Row],[KESİLECEK PARÇA BOYU]]+$O$2)))*(SK[[#This Row],[KESİLECEK PARÇA BOYU]]+$O$2) ), 0 ) ), 0 ), 0) -> 0 | K16: =IFERROR( IF( IF( MOD(SK[[#This Row],[BOY]],SK[[#This Row],[KESİLECEK PARÇA BOYU]])-$O$2*INT(SK[[#This Row],[BOY]]/SK[[#This Row],[KESİLECEK PARÇA BOYU]])>$P$2, (MOD(SK[[#This Row],[BOY]],SK[[#This Row],[KESİLECEK PARÇA BOYU]])-$O$2*INT(SK[[#This Row],[BOY]]/SK[[#This Row],[KESİLECEK PARÇA BOYU]])), 0 )>0,IF( MOD(SK[[#This Row],[BOY]],SK[[#This Row],[KESİLECEK PARÇA BOYU]])-$O$2*INT(SK[[#This Row],[BOY]]/SK[[#This Row],[KESİLECEK PARÇA BOYU]])>$P$2, (MOD(SK[[#This Row],[BOY]],SK[[#This Row],[KESİLECEK PARÇA BOYU]])-$O$2*INT(SK[[#This Row],[BOY]]/SK[[#This Row],[KESİLECEK PARÇA BOYU]])), 0 ),0),0) -> 0 | L16: =IFERROR(IF(SK[[#This Row],[BOY]]-(SK[[#This Row],[KESİLECEK PARÇA BOYU]]+$O$2)*MOD(SK[[#This Row],[KESİLECEK PARÇA ADEDİ ]],INT(SK[[#This Row],[BOY]]/(SK[[#This Row],[KESİLECEK PARÇA BOYU]]+$O$2)))<SK[[#This Row],[BOY]],SK[[#This Row],[BOY]]-(SK[[#This Row],[KESİLECEK PARÇA BOYU]]+$O$2)*MOD(SK[[#This Row],[KESİLECEK PARÇA ADEDİ ]],INT(SK[[#This Row],[BOY]]/(SK[[#This Row],[KESİLECEK PARÇA BOYU]]+$O$2))),0),0) -> 0
A17: 45895 | B17: 225 | C17: KUTU PROFİL | D17: RHS 100X50X3 | E17: S235JR | F17: 4 | G17: 4815 | H17: =IFERROR(IF( SK[[#This Row],[KESİLECEK PARÇA ADEDİ ]]*SK[[#This Row],[KESİLECEK PARÇA BOYU]] < SK[[#This Row],[BOY]] - 3*ROUNDUP(SK[[#This Row],[BOY]]/SK[[#This Row],[KESİLECEK PARÇA BOYU]] - 1, 0), 1, ROUNDUP(SK[[#This Row],[KESİLECEK PARÇA ADEDİ ]]/INT(SK[[#This Row],[BOY]]/(SK[[#This Row],[KESİLECEK PARÇA BOYU]]+$O$2)), 0) ),0) -> 2 | I17: 12000 | J17: =IFERROR( IF(SK[[#This Row],[GEREKLİ ADET]]=1, SK[[#This Row],[BOY]]-SK[[#This Row],[KESİLECEK PARÇA ADEDİ ]]*(SK[[#This Row],[KESİLECEK PARÇA BOYU]]+$O$2), IF( MOD(SK[[#This Row],[BOY]],SK[[#This Row],[KESİLECEK PARÇA BOYU]])-$O$2*INT(SK[[#This Row],[BOY]]/SK[[#This Row],[KESİLECEK PARÇA BOYU]])>$P$2, (MOD(SK[[#This Row],[BOY]],SK[[#This Row],[KESİLECEK PARÇA BOYU]])-$O$2*INT(SK[[#This Row],[BOY]]/SK[[#This Row],[KESİLECEK PARÇA BOYU]]))*SK[[#This Row],[GEREKLİ ADET]], 0 ) ) + IF(SK[[#This Row],[GEREKLİ ADET]]>1, IF( INT((SK[[#This Row],[BOY]]+$O$2)/(SK[[#This Row],[KESİLECEK PARÇA BOYU]]+$O$2))=0, 0, IF( (SK[[#This Row],[BOY]]-MOD(SK[[#This Row],[KESİLECEK PARÇA ADEDİ ]], INT((SK[[#This Row],[BOY]]+$O$2)/(SK[[#This Row],[KESİLECEK PARÇA BOYU]]+$O$2)) )*(SK[[#This Row],[KESİLECEK PARÇA BOYU]]+$O$2))>$P$2, IF( MOD(SK[[#This Row],[KESİLECEK PARÇA ADEDİ ]], INT((SK[[#This Row],[BOY]]+$O$2)/(SK[[#This Row],[KESİLECEK PARÇA BOYU]]+$O$2)))=0, 0, SK[[#This Row],[BOY]]-MOD(SK[[#This Row],[KESİLECEK PARÇA ADEDİ ]], INT((SK[[#This Row],[BOY]]+$O$2)/(SK[[#This Row],[KESİLECEK PARÇA BOYU]]+$O$2)))*(SK[[#This Row],[KESİLECEK PARÇA BOYU]]+$O$2) ), 0 ) ), 0 ), 0) -> 4728 | K17: =IFERROR( IF( IF( MOD(SK[[#This Row],[BOY]],SK[[#This Row],[KESİLECEK PARÇA BOYU]])-$O$2*INT(SK[[#This Row],[BOY]]/SK[[#This Row],[KESİLECEK PARÇA BOYU]])>$P$2, (MOD(SK[[#This Row],[BOY]],SK[[#This Row],[KESİLECEK PARÇA BOYU]])-$O$2*INT(SK[[#This Row],[BOY]]/SK[[#This Row],[KESİLECEK PARÇA BOYU]])), 0 )>0,IF( MOD(SK[[#This Row],[BOY]],SK[[#This Row],[KESİLECEK PARÇA BOYU]])-$O$2*INT(SK[[#This Row],[BOY]]/SK[[#This Row],[KESİLECEK PARÇA BOYU]])>$P$2, (MOD(SK[[#This Row],[BOY]],SK[[#This Row],[KESİLECEK PARÇA BOYU]])-$O$2*INT(SK[[#This Row],[BOY]]/SK[[#This Row],[KESİLECEK PARÇA BOYU]])), 0 ),0),0) -> 2364 | L17: =IFERROR(IF(SK[[#This Row],[BOY]]-(SK[[#This Row],[KESİLECEK PARÇA BOYU]]+$O$2)*MOD(SK[[#This Row],[KESİLECEK PARÇA ADEDİ ]],INT(SK[[#This Row],[BOY]]/(SK[[#This Row],[KESİLECEK PARÇA BOYU]]+$O$2)))<SK[[#This Row],[BOY]],SK[[#This Row],[BOY]]-(SK[[#This Row],[KESİLECEK PARÇA BOYU]]+$O$2)*MOD(SK[[#This Row],[KESİLECEK PARÇA ADEDİ ]],INT(SK[[#This Row],[BOY]]/(SK[[#This Row],[KESİLECEK PARÇA BOYU]]+$O$2))),0),0) -> 0
H18: =IFERROR(IF( SK[[#This Row],[KESİLECEK PARÇA ADEDİ ]]*SK[[#This Row],[KESİLECEK PARÇA BOYU]] < SK[[#This Row],[BOY]] - 3*ROUNDUP(SK[[#This Row],[BOY]]/SK[[#This Row],[KESİLECEK PARÇA BOYU]] - 1, 0), 1, ROUNDUP(SK[[#This Row],[KESİLECEK PARÇA ADEDİ ]]/INT(SK[[#This Row],[BOY]]/(SK[[#This Row],[KESİLECEK PARÇA BOYU]]+$O$2)), 0) ),0) -> 0 | J18: =IFERROR( IF(SK[[#This Row],[GEREKLİ ADET]]=1, SK[[#This Row],[BOY]]-SK[[#This Row],[KESİLECEK PARÇA ADEDİ ]]*(SK[[#This Row],[KESİLECEK PARÇA BOYU]]+$O$2), IF( MOD(SK[[#This Row],[BOY]],SK[[#This Row],[KESİLECEK PARÇA BOYU]])-$O$2*INT(SK[[#This Row],[BOY]]/SK[[#This Row],[KESİLECEK PARÇA BOYU]])>$P$2, (MOD(SK[[#This Row],[BOY]],SK[[#This Row],[KESİLECEK PARÇA BOYU]])-$O$2*INT(SK[[#This Row],[BOY]]/SK[[#This Row],[KESİLECEK PARÇA BOYU]]))*SK[[#This Row],[GEREKLİ ADET]], 0 ) ) + IF(SK[[#This Row],[GEREKLİ ADET]]>1, IF( INT((SK[[#This Row],[BOY]]+$O$2)/(SK[[#This Row],[KESİLECEK PARÇA BOYU]]+$O$2))=0, 0, IF( (SK[[#This Row],[BOY]]-MOD(SK[[#This Row],[KESİLECEK PARÇA ADEDİ ]], INT((SK[[#This Row],[BOY]]+$O$2)/(SK[[#This Row],[KESİLECEK PARÇA BOYU]]+$O$2)) )*(SK[[#This Row],[KESİLECEK PARÇA BOYU]]+$O$2))>$P$2, IF( MOD(SK[[#This Row],[KESİLECEK PARÇA ADEDİ ]], INT((SK[[#This Row],[BOY]]+$O$2)/(SK[[#This Row],[KESİLECEK PARÇA BOYU]]+$O$2)))=0, 0, SK[[#This Row],[BOY]]-MOD(SK[[#This Row],[KESİLECEK PARÇA ADEDİ ]], INT((SK[[#This Row],[BOY]]+$O$2)/(SK[[#This Row],[KESİLECEK PARÇA BOYU]]+$O$2)))*(SK[[#This Row],[KESİLECEK PARÇA BOYU]]+$O$2) ), 0 ) ), 0 ), 0) -> 0 | K18: =IFERROR( IF( IF( MOD(SK[[#This Row],[BOY]],SK[[#This Row],[KESİLECEK PARÇA BOYU]])-$O$2*INT(SK[[#This Row],[BOY]]/SK[[#This Row],[KESİLECEK PARÇA BOYU]])>$P$2, (MOD(SK[[#This Row],[BOY]],SK[[#This Row],[KESİLECEK PARÇA BOYU]])-$O$2*INT(SK[[#This Row],[BOY]]/SK[[#This Row],[KESİLECEK PARÇA BOYU]])), 0 )>0,IF( MOD(SK[[#This Row],[BOY]],SK[[#This Row],[KESİLECEK PARÇA BOYU]])-$O$2*INT(SK[[#This Row],[BOY]]/SK[[#This Row],[KESİLECEK PARÇA BOYU]])>$P$2, (MOD(SK[[#This Row],[BOY]],SK[[#This Row],[KESİLECEK PARÇA BOYU]])-$O$2*INT(SK[[#This Row],[BOY]]/SK[[#This Row],[KESİLECEK PARÇA BOYU]])), 0 ),0),0) -> 0 | L18: =IFERROR(IF(SK[[#This Row],[BOY]]-(SK[[#This Row],[KESİLECEK PARÇA BOYU]]+$O$2)*MOD(SK[[#This Row],[KESİLECEK PARÇA ADEDİ ]],INT(SK[[#This Row],[BOY]]/(SK[[#This Row],[KESİLECEK PARÇA BOYU]]+$O$2)))<SK[[#This Row],[BOY]],SK[[#This Row],[BOY]]-(SK[[#This Row],[KESİLECEK PARÇA BOYU]]+$O$2)*MOD(SK[[#This Row],[KESİLECEK PARÇA ADEDİ ]],INT(SK[[#This Row],[BOY]]/(SK[[#This Row],[KESİLECEK PARÇA BOYU]]+$O$2))),0),0) -> 0
H19: =IFERROR(IF( SK[[#This Row],[KESİLECEK PARÇA ADEDİ ]]*SK[[#This Row],[KESİLECEK PARÇA BOYU]] < SK[[#This Row],[BOY]] - 3*ROUNDUP(SK[[#This Row],[BOY]]/SK[[#This Row],[KESİLECEK PARÇA BOYU]] - 1, 0), 1, ROUNDUP(SK[[#This Row],[KESİLECEK PARÇA ADEDİ ]]/INT(SK[[#This Row],[BOY]]/(SK[[#This Row],[KESİLECEK PARÇA BOYU]]+$O$2)), 0) ),0) -> 0 | J19: =IFERROR( IF(SK[[#This Row],[GEREKLİ ADET]]=1, SK[[#This Row],[BOY]]-SK[[#This Row],[KESİLECEK PARÇA ADEDİ ]]*(SK[[#This Row],[KESİLECEK PARÇA BOYU]]+$O$2), IF( MOD(SK[[#This Row],[BOY]],SK[[#This Row],[KESİLECEK PARÇA BOYU]])-$O$2*INT(SK[[#This Row],[BOY]]/SK[[#This Row],[KESİLECEK PARÇA BOYU]])>$P$2, (MOD(SK[[#This Row],[BOY]],SK[[#This Row],[KESİLECEK PARÇA BOYU]])-$O$2*INT(SK[[#This Row],[BOY]]/SK[[#This Row],[KESİLECEK PARÇA BOYU]]))*SK[[#This Row],[GEREKLİ ADET]], 0 ) ) + IF(SK[[#This Row],[GEREKLİ ADET]]>1, IF( INT((SK[[#This Row],[BOY]]+$O$2)/(SK[[#This Row],[KESİLECEK PARÇA BOYU]]+$O$2))=0, 0, IF( (SK[[#This Row],[BOY]]-MOD(SK[[#This Row],[KESİLECEK PARÇA ADEDİ ]], INT((SK[[#This Row],[BOY]]+$O$2)/(SK[[#This Row],[KESİLECEK PARÇA BOYU]]+$O$2)) )*(SK[[#This Row],[KESİLECEK PARÇA BOYU]]+$O$2))>$P$2, IF( MOD(SK[[#This Row],[KESİLECEK PARÇA ADEDİ ]], INT((SK[[#This Row],[BOY]]+$O$2)/(SK[[#This Row],[KESİLECEK PARÇA BOYU]]+$O$2)))=0, 0, SK[[#This Row],[BOY]]-MOD(SK[[#This Row],[KESİLECEK PARÇA ADEDİ ]], INT((SK[[#This Row],[BOY]]+$O$2)/(SK[[#This Row],[KESİLECEK PARÇA BOYU]]+$O$2)))*(SK[[#This Row],[KESİLECEK PARÇA BOYU]]+$O$2) ), 0 ) ), 0 ), 0) -> 0 | K19: =IFERROR( IF( IF( MOD(SK[[#This Row],[BOY]],SK[[#This Row],[KESİLECEK PARÇA BOYU]])-$O$2*INT(SK[[#This Row],[BOY]]/SK[[#This Row],[KESİLECEK PARÇA BOYU]])>$P$2, (MOD(SK[[#This Row],[BOY]],SK[[#This Row],[KESİLECEK PARÇA BOYU]])-$O$2*INT(SK[[#This Row],[BOY]]/SK[[#This Row],[KESİLECEK PARÇA BOYU]])), 0 )>0,IF( MOD(SK[[#This Row],[BOY]],SK[[#This Row],[KESİLECEK PARÇA BOYU]])-$O$2*INT(SK[[#This Row],[BOY]]/SK[[#This Row],[KESİLECEK PARÇA BOYU]])>$P$2, (MOD(SK[[#This Row],[BOY]],SK[[#This Row],[KESİLECEK PARÇA BOYU]])-$O$2*INT(SK[[#This Row],[BOY]]/SK[[#This Row],[KESİLECEK PARÇA BOYU]])), 0 ),0),0) -> 0 | L19: =IFERROR(IF(SK[[#This Row],[BOY]]-(SK[[#This Row],[KESİLECEK PARÇA BOYU]]+$O$2)*MOD(SK[[#This Row],[KESİLECEK PARÇA ADEDİ ]],INT(SK[[#This Row],[BOY]]/(SK[[#This Row],[KESİLECEK PARÇA BOYU]]+$O$2)))<SK[[#This Row],[BOY]],SK[[#This Row],[BOY]]-(SK[[#This Row],[KESİLECEK PARÇA BOYU]]+$O$2)*MOD(SK[[#This Row],[KESİLECEK PARÇA ADEDİ ]],INT(SK[[#This Row],[BOY]]/(SK[[#This Row],[KESİLECEK PARÇA BOYU]]+$O$2))),0),0) -> 0
H20: =IFERROR(IF( SK[[#This Row],[KESİLECEK PARÇA ADEDİ ]]*SK[[#This Row],[KESİLECEK PARÇA BOYU]] < SK[[#This Row],[BOY]] - 3*ROUNDUP(SK[[#This Row],[BOY]]/SK[[#This Row],[KESİLECEK PARÇA BOYU]] - 1, 0), 1, ROUNDUP(SK[[#This Row],[KESİLECEK PARÇA ADEDİ ]]/INT(SK[[#This Row],[BOY]]/(SK[[#This Row],[KESİLECEK PARÇA BOYU]]+$O$2)), 0) ),0) -> 0 | I20: 6000 | J20: =IFERROR( IF(SK[[#This Row],[GEREKLİ ADET]]=1, SK[[#This Row],[BOY]]-SK[[#This Row],[KESİLECEK PARÇA ADEDİ ]]*(SK[[#This Row],[KESİLECEK PARÇA BOYU]]+$O$2), IF( MOD(SK[[#This Row],[BOY]],SK[[#This Row],[KESİLECEK PARÇA BOYU]])-$O$2*INT(SK[[#This Row],[BOY]]/SK[[#This Row],[KESİLECEK PARÇA BOYU]])>$P$2, (MOD(SK[[#This Row],[BOY]],SK[[#This Row],[KESİLECEK PARÇA BOYU]])-$O$2*INT(SK[[#This Row],[BOY]]/SK[[#This Row],[KESİLECEK PARÇA BOYU]]))*SK[[#This Row],[GEREKLİ ADET]], 0 ) ) + IF(SK[[#This Row],[GEREKLİ ADET]]>1, IF( INT((SK[[#This Row],[BOY]]+$O$2)/(SK[[#This Row],[KESİLECEK PARÇA BOYU]]+$O$2))=0, 0, IF( (SK[[#This Row],[BOY]]-MOD(SK[[#This Row],[KESİLECEK PARÇA ADEDİ ]], INT((SK[[#This Row],[BOY]]+$O$2)/(SK[[#This Row],[KESİLECEK PARÇA BOYU]]+$O$2)) )*(SK[[#This Row],[KESİLECEK PARÇA BOYU]]+$O$2))>$P$2, IF( MOD(SK[[#This Row],[KESİLECEK PARÇA ADEDİ ]], INT((SK[[#This Row],[BOY]]+$O$2)/(SK[[#This Row],[KESİLECEK PARÇA BOYU]]+$O$2)))=0, 0, SK[[#This Row],[BOY]]-MOD(SK[[#This Row],[KESİLECEK PARÇA ADEDİ ]], INT((SK[[#This Row],[BOY]]+$O$2)/(SK[[#This Row],[KESİLECEK PARÇA BOYU]]+$O$2)))*(SK[[#This Row],[KESİLECEK PARÇA BOYU]]+$O$2) ), 0 ) ), 0 ), 0) -> 0 | K20: =IFERROR( IF( IF( MOD(SK[[#This Row],[BOY]],SK[[#This Row],[KESİLECEK PARÇA BOYU]])-$O$2*INT(SK[[#This Row],[BOY]]/SK[[#This Row],[KESİLECEK PARÇA BOYU]])>$P$2, (MOD(SK[[#This Row],[BOY]],SK[[#This Row],[KESİLECEK PARÇA BOYU]])-$O$2*INT(SK[[#This Row],[BOY]]/SK[[#This Row],[KESİLECEK PARÇA BOYU]])), 0 )>0,IF( MOD(SK[[#This Row],[BOY]],SK[[#This Row],[KESİLECEK PARÇA BOYU]])-$O$2*INT(SK[[#This Row],[BOY]]/SK[[#This Row],[KESİLECEK PARÇA BOYU]])>$P$2, (MOD(SK[[#This Row],[BOY]],SK[[#This Row],[KESİLECEK PARÇA BOYU]])-$O$2*INT(SK[[#This Row],[BOY]]/SK[[#This Row],[KESİLECEK PARÇA BOYU]])), 0 ),0),0) -> 0 | L20: =IFERROR(IF(SK[[#This Row],[BOY]]-(SK[[#This Row],[KESİLECEK PARÇA BOYU]]+$O$2)*MOD(SK[[#This Row],[KESİLECEK PARÇA ADEDİ ]],INT(SK[[#This Row],[BOY]]/(SK[[#This Row],[KESİLECEK PARÇA BOYU]]+$O$2)))<SK[[#This Row],[BOY]],SK[[#This Row],[BOY]]-(SK[[#This Row],[KESİLECEK PARÇA BOYU]]+$O$2)*MOD(SK[[#This Row],[KESİLECEK PARÇA ADEDİ ]],INT(SK[[#This Row],[BOY]]/(SK[[#This Row],[KESİLECEK PARÇA BOYU]]+$O$2))),0),0) -> 0
H21: =IFERROR(IF( SK[[#This Row],[KESİLECEK PARÇA ADEDİ ]]*SK[[#This Row],[KESİLECEK PARÇA BOYU]] < SK[[#This Row],[BOY]] - 3*ROUNDUP(SK[[#This Row],[BOY]]/SK[[#This Row],[KESİLECEK PARÇA BOYU]] - 1, 0), 1, ROUNDUP(SK[[#This Row],[KESİLECEK PARÇA ADEDİ ]]/INT(SK[[#This Row],[BOY]]/(SK[[#This Row],[KESİLECEK PARÇA BOYU]]+$O$2)), 0) ),0) -> 0 | J21: =IFERROR( IF(SK[[#This Row],[GEREKLİ ADET]]=1, SK[[#This Row],[BOY]]-SK[[#This Row],[KESİLECEK PARÇA ADEDİ ]]*(SK[[#This Row],[KESİLECEK PARÇA BOYU]]+$O$2), IF( MOD(SK[[#This Row],[BOY]],SK[[#This Row],[KESİLECEK PARÇA BOYU]])-$O$2*INT(SK[[#This Row],[BOY]]/SK[[#This Row],[KESİLECEK PARÇA BOYU]])>$P$2, (MOD(SK[[#This Row],[BOY]],SK[[#This Row],[KESİLECEK PARÇA BOYU]])-$O$2*INT(SK[[#This Row],[BOY]]/SK[[#This Row],[KESİLECEK PARÇA BOYU]]))*SK[[#This Row],[GEREKLİ ADET]], 0 ) ) + IF(SK[[#This Row],[GEREKLİ ADET]]>1, IF( INT((SK[[#This Row],[BOY]]+$O$2)/(SK[[#This Row],[KESİLECEK PARÇA BOYU]]+$O$2))=0, 0, IF( (SK[[#This Row],[BOY]]-MOD(SK[[#This Row],[KESİLECEK PARÇA ADEDİ ]], INT((SK[[#This Row],[BOY]]+$O$2)/(SK[[#This Row],[KESİLECEK PARÇA BOYU]]+$O$2)) )*(SK[[#This Row],[KESİLECEK PARÇA BOYU]]+$O$2))>$P$2, IF( MOD(SK[[#This Row],[KESİLECEK PARÇA ADEDİ ]], INT((SK[[#This Row],[BOY]]+$O$2)/(SK[[#This Row],[KESİLECEK PARÇA BOYU]]+$O$2)))=0, 0, SK[[#This Row],[BOY]]-MOD(SK[[#This Row],[KESİLECEK PARÇA ADEDİ ]], INT((SK[[#This Row],[BOY]]+$O$2)/(SK[[#This Row],[KESİLECEK PARÇA BOYU]]+$O$2)))*(SK[[#This Row],[KESİLECEK PARÇA BOYU]]+$O$2) ), 0 ) ), 0 ), 0) -> 0 | K21: =IFERROR( IF( IF( MOD(SK[[#This Row],[BOY]],SK[[#This Row],[KESİLECEK PARÇA BOYU]])-$O$2*INT(SK[[#This Row],[BOY]]/SK[[#This Row],[KESİLECEK PARÇA BOYU]])>$P$2, (MOD(SK[[#This Row],[BOY]],SK[[#This Row],[KESİLECEK PARÇA BOYU]])-$O$2*INT(SK[[#This Row],[BOY]]/SK[[#This Row],[KESİLECEK PARÇA BOYU]])), 0 )>0,IF( MOD(SK[[#This Row],[BOY]],SK[[#This Row],[KESİLECEK PARÇA BOYU]])-$O$2*INT(SK[[#This Row],[BOY]]/SK[[#This Row],[KESİLECEK PARÇA BOYU]])>$P$2, (MOD(SK[[#This Row],[BOY]],SK[[#This Row],[KESİLECEK PARÇA BOYU]])-$O$2*INT(SK[[#This Row],[BOY]]/SK[[#This Row],[KESİLECEK PARÇA BOYU]])), 0 ),0),0) -> 0 | L21: =IFERROR(IF(SK[[#This Row],[BOY]]-(SK[[#This Row],[KESİLECEK PARÇA BOYU]]+$O$2)*MOD(SK[[#This Row],[KESİLECEK PARÇA ADEDİ ]],INT(SK[[#This Row],[BOY]]/(SK[[#This Row],[KESİLECEK PARÇA BOYU]]+$O$2)))<SK[[#This Row],[BOY]],SK[[#This Row],[BOY]]-(SK[[#This Row],[KESİLECEK PARÇA BOYU]]+$O$2)*MOD(SK[[#This Row],[KESİLECEK PARÇA ADEDİ ]],INT(SK[[#This Row],[BOY]]/(SK[[#This Row],[KESİLECEK PARÇA BOYU]]+$O$2))),0),0) -> 0
H22: =IFERROR(IF( SK[[#This Row],[KESİLECEK PARÇA ADEDİ ]]*SK[[#This Row],[KESİLECEK PARÇA BOYU]] < SK[[#This Row],[BOY]] - 3*ROUNDUP(SK[[#This Row],[BOY]]/SK[[#This Row],[KESİLECEK PARÇA BOYU]] - 1, 0), 1, ROUNDUP(SK[[#This Row],[KESİLECEK PARÇA ADEDİ ]]/INT(SK[[#This Row],[BOY]]/(SK[[#This Row],[KESİLECEK PARÇA BOYU]]+$O$2)), 0) ),0) -> 0 | I22: 12000 | J22: =IFERROR( IF(SK[[#This Row],[GEREKLİ ADET]]=1, SK[[#This Row],[BOY]]-SK[[#This Row],[KESİLECEK PARÇA ADEDİ ]]*(SK[[#This Row],[KESİLECEK PARÇA BOYU]]+$O$2), IF( MOD(SK[[#This Row],[BOY]],SK[[#This Row],[KESİLECEK PARÇA BOYU]])-$O$2*INT(SK[[#This Row],[BOY]]/SK[[#This Row],[KESİLECEK PARÇA BOYU]])>$P$2, (MOD(SK[[#This Row],[BOY]],SK[[#This Row],[KESİLECEK PARÇA BOYU]])-$O$2*INT(SK[[#This Row],[BOY]]/SK[[#This Row],[KESİLECEK PARÇA BOYU]]))*SK[[#This Row],[GEREKLİ ADET]], 0 ) ) + IF(SK[[#This Row],[GEREKLİ ADET]]>1, IF( INT((SK[[#This Row],[BOY]]+$O$2)/(SK[[#This Row],[KESİLECEK PARÇA BOYU]]+$O$2))=0, 0, IF( (SK[[#This Row],[BOY]]-MOD(SK[[#This Row],[KESİLECEK PARÇA ADEDİ ]], INT((SK[[#This Row],[BOY]]+$O$2)/(SK[[#This Row],[KESİLECEK PARÇA BOYU]]+$O$2)) )*(SK[[#This Row],[KESİLECEK PARÇA BOYU]]+$O$2))>$P$2, IF( MOD(SK[[#This Row],[KESİLECEK PARÇA ADEDİ ]], INT((SK[[#This Row],[BOY]]+$O$2)/(SK[[#This Row],[KESİLECEK PARÇA BOYU]]+$O$2)))=0, 0, SK[[#This Row],[BOY]]-MOD(SK[[#This Row],[KESİLECEK PARÇA ADEDİ ]], INT((SK[[#This Row],[BOY]]+$O$2)/(SK[[#This Row],[KESİLECEK PARÇA BOYU]]+$O$2)))*(SK[[#This Row],[KESİLECEK PARÇA BOYU]]+$O$2) ), 0 ) ), 0 ), 0) -> 0 | K22: =IFERROR( IF( IF( MOD(SK[[#This Row],[BOY]],SK[[#This Row],[KESİLECEK PARÇA BOYU]])-$O$2*INT(SK[[#This Row],[BOY]]/SK[[#This Row],[KESİLECEK PARÇA BOYU]])>$P$2, (MOD(SK[[#This Row],[BOY]],SK[[#This Row],[KESİLECEK PARÇA BOYU]])-$O$2*INT(SK[[#This Row],[BOY]]/SK[[#This Row],[KESİLECEK PARÇA BOYU]])), 0 )>0,IF( MOD(SK[[#This Row],[BOY]],SK[[#This Row],[KESİLECEK PARÇA BOYU]])-$O$2*INT(SK[[#This Row],[BOY]]/SK[[#This Row],[KESİLECEK PARÇA BOYU]])>$P$2, (MOD(SK[[#This Row],[BOY]],SK[[#This Row],[KESİLECEK PARÇA BOYU]])-$O$2*INT(SK[[#This Row],[BOY]]/SK[[#This Row],[KESİLECEK PARÇA BOYU]])), 0 ),0),0) -> 0 | L22: =IFERROR(IF(SK[[#This Row],[BOY]]-(SK[[#This Row],[KESİLECEK PARÇA BOYU]]+$O$2)*MOD(SK[[#This Row],[KESİLECEK PARÇA ADEDİ ]],INT(SK[[#This Row],[BOY]]/(SK[[#This Row],[KESİLECEK PARÇA BOYU]]+$O$2)))<SK[[#This Row],[BOY]],SK[[#This Row],[BOY]]-(SK[[#This Row],[KESİLECEK PARÇA BOYU]]+$O$2)*MOD(SK[[#This Row],[KESİLECEK PARÇA ADEDİ ]],INT(SK[[#This Row],[BOY]]/(SK[[#This Row],[KESİLECEK PARÇA BOYU]]+$O$2))),0),0) -> 0
A23: 45895 | B23: 318 | C23: BORU PROFİL | D23: CHS 76,3X4 | E23: S355J2 | F23: 2 | G23: 2998 | H23: =IFERROR(IF( SK[[#This Row],[KESİLECEK PARÇA ADEDİ ]]*SK[[#This Row],[KESİLECEK PARÇA BOYU]] < SK[[#This Row],[BOY]] - 3*ROUNDUP(SK[[#This Row],[BOY]]/SK[[#This Row],[KESİLECEK PARÇA BOYU]] - 1, 0), 1, ROUNDUP(SK[[#This Row],[KESİLECEK PARÇA ADEDİ ]]/INT(SK[[#This Row],[BOY]]/(SK[[#This Row],[KESİLECEK PARÇA BOYU]]+$O$2)), 0) ),0) -> 2 | I23: 6000 | J23: =IFERROR( IF(SK[[#This Row],[GEREKLİ ADET]]=1, SK[[#This Row],[BOY]]-SK[[#This Row],[KESİLECEK PARÇA ADEDİ ]]*(SK[[#This Row],[KESİLECEK PARÇA BOYU]]+$O$2), IF( MOD(SK[[#This Row],[BOY]],SK[[#This Row],[KESİLECEK PARÇA BOYU]])-$O$2*INT(SK[[#This Row],[BOY]]/SK[[#This Row],[KESİLECEK PARÇA BOYU]])>$P$2, (MOD(SK[[#This Row],[BOY]],SK[[#This Row],[KESİLECEK PARÇA BOYU]])-$O$2*INT(SK[[#This Row],[BOY]]/SK[[#This Row],[KESİLECEK PARÇA BOYU]]))*SK[[#This Row],[GEREKLİ ADET]], 0 ) ) + IF(SK[[#This Row],[GEREKLİ ADET]]>1, IF( INT((SK[[#This Row],[BOY]]+$O$2)/(SK[[#This Row],[KESİLECEK PARÇA BOYU]]+$O$2))=0, 0, IF( (SK[[#This Row],[BOY]]-MOD(SK[[#This Row],[KESİLECEK PARÇA ADEDİ ]], INT((SK[[#This Row],[BOY]]+$O$2)/(SK[[#This Row],[KESİLECEK PARÇA BOYU]]+$O$2)) )*(SK[[#This Row],[KESİLECEK PARÇA BOYU]]+$O$2))>$P$2, IF( MOD(SK[[#This Row],[KESİLECEK PARÇA ADEDİ ]], INT((SK[[#This Row],[BOY]]+$O$2)/(SK[[#This Row],[KESİLECEK PARÇA BOYU]]+$O$2)))=0, 0, SK[[#This Row],[BOY]]-MOD(SK[[#This Row],[KESİLECEK PARÇA ADEDİ ]], INT((SK[[#This Row],[BOY]]+$O$2)/(SK[[#This Row],[KESİLECEK PARÇA BOYU]]+$O$2)))*(SK[[#This Row],[KESİLECEK PARÇA BOYU]]+$O$2) ), 0 ) ), 0 ), 0) -> 0 | K23: =IFERROR( IF( IF( MOD(SK[[#This Row],[BOY]],SK[[#This Row],[KESİLECEK PARÇA BOYU]])-$O$2*INT(SK[[#This Row],[BOY]]/SK[[#This Row],[KESİLECEK PARÇA BOYU]])>$P$2, (MOD(SK[[#This Row],[BOY]],SK[[#This Row],[KESİLECEK PARÇA BOYU]])-$O$2*INT(SK[[#This Row],[BOY]]/SK[[#This Row],[KESİLECEK PARÇA BOYU]])), 0 )>0,IF( MOD(SK[[#This Row],[BOY]],SK[[#This Row],[KESİLECEK PARÇA BOYU]])-$O$2*INT(SK[[#This Row],[BOY]]/SK[[#This Row],[KESİLECEK PARÇA BOYU]])>$P$2, (MOD(SK[[#This Row],[BOY]],SK[[#This Row],[KESİLECEK PARÇA BOYU]])-$O$2*INT(SK[[#This Row],[BOY]]/SK[[#This Row],[KESİLECEK PARÇA BOYU]])), 0 ),0),0) -> 0 | L23: =IFERROR(IF(SK[[#This Row],[BOY]]-(SK[[#This Row],[KESİLECEK PARÇA BOYU]]+$O$2)*MOD(SK[[#This Row],[KESİLECEK PARÇA ADEDİ ]],INT(SK[[#This Row],[BOY]]/(SK[[#This Row],[KESİLECEK PARÇA BOYU]]+$O$2)))<SK[[#This Row],[BOY]],SK[[#This Row],[BOY]]-(SK[[#This Row],[KESİLECEK PARÇA BOYU]]+$O$2)*MOD(SK[[#This Row],[KESİLECEK PARÇA ADEDİ ]],INT(SK[[#This Row],[BOY]]/(SK[[#This Row],[KESİLECEK PARÇA BOYU]]+$O$2))),0),0) -> 0
